Workbook

Sheet Guide
B1: دليل الاستخدام | User guide
B3: ملف تحليل نتائج الطلاب (Year 2 – Year 13): التحصيل والتقدم مع المعلمين والبلوكات والمجموعات — أعداد مجمّعة فقط، بلا أسماء طلاب.
B5: كيف تبدأ (5 خطوات)
B6: 1 | C6: Settings: راجع العام الدراسي وسلم الدرجات وحدود At/Above ومفتاح الأحكام (الخلايا الصفراء). مفتاح التقدم افتراضه منسوخ من مفتاح التحصيل — اعتمد قيمك.
B7: 2 | C7: Classes / Teachers: راجع ربط المعلم بالصف (مأخوذ من جدول MOE بتاريخ 01-OCT-26). الصفوف التي ظهر فيها أكثر من معلم تُركت فارغة ومكتوب سبب ذلك — اختر المعلم الصحيح. صحّح أي اسم معروض من Teachers.
B8: 3 | C8: Data: كل سطر = عدد الطلاب المشتركين في (كود الصف · الفترة · المجموعة · Start Point · Current Grade). اختر القيم من القوائم؛ المعلم والصف والبلوك والمادة تظهر تلقائياً.
B9: 4 | C9: Baseline: أدخل Current = علامة نقطة البداية واترك Start فارغاً (لا تقدم لـ Baseline). Term 1/2/3: Start = علامة Baseline، Current = علامة الفترة.
B10: 5 | C10: افتح Dashboard / Year_Panel / Teacher_Report واختر الفلاتر. Checks تعرض أي عدم اتساق في الأعداد، وTests تتحقق من صحة الحسابات.
B11: قواعد الحساب
B12: At & Above | C12: عدد الطلاب عند AT فأعلى ÷ عدد الطلاب ذوي النتائج الفعلية (العتبة قابلة للتعديل في Settings). لا علاقة لها بالعلامة AT+.
B13: Above | C13: عدد الطلاب عند AB فأعلى ÷ عدد الطلاب ذوي النتائج الفعلية.
B14: الغياب / لا نتيجة | C14: اختر Current = NR (أو اتركه فارغاً): ليس U وليس صفراً، ويُستبعد من مقام التحصيل. U نتيجة فعلية تدخل المقام.
B15: التقدم | C15: يُصنَّف بالبحث (Lookup) في Progress_Matrix عن Start Point والعلامة الحالية — لا طرح ولا قاعدة ارتفاع/ثبات عامة. Expected & Better = (Expected+Better)÷الحالات القابلة للتصنيف؛ Better = Better÷الحالات القابلة للتصنيف.
B16: U في التقدم | C16: U غير موجودة في المصفوفة المرفقة، فلا حكم لها: حالات Start=U أو Current=U تُستبعد من مقام التقدم ويُعرض عددها (بطاقة «حالات تقدم» وجدول الصفوف) حتى تُعتمد قاعدة.
B17: Current فقط | C17: من لديه Current بلا Start يدخل التحصيل ولا يدخل التقدم (يُعرض عددهم).
B18: المجموعات | C18: إجمالي الصف · الأولاد · البنات · SEND · Gifted & Talented · الإماراتيون. متداخلة: لا يُجمع بعضها إلى بعض للحصول على إجمالي الصف. أدخل «إجمالي الصف» كسطور مستقلة.
B19: حكم الأداء | C19: At&Above ≤15% ← Very Weak · أكبر من 15% وأقل من 75% ← Weak · ≥75%: Above أقل من 50% ← Acceptable · 50–60% ← Good · أكبر من 60% وأقل من 75% ← Very Good · ≥75% ← Outstanding. الحدود متصلة ولا تُقرَّب النسبة قبل الحكم (60.5% ← Very Good). تُطبَّق على التقدم بمفتاح مستقل.
B20: الإجماليات | C20: كل الإجماليات من مجموع الأعداد، لا من متوسط نسب الصفوف. عند مقام صفري يظهر «لا توجد بيانات».
B21: الحاسبتان
B22: Target_Attain | C22: أدخل عدد الطلاب ونسبتي Above وAt&Above وخيار التقريب (أقرب نسبة / على الأقل) ← عدد لكل علامة بقاعدة أوزان قابلة للتعديل، ثم النسب المحققة والحكم والفارق. مثال: 40 / 55% / 93% ← 22 و37 (أو 38).
B23: Target_Progress | C23: أدخل عدد الطلاب عند كل Start Point ونسبتي Better وExpected&Better ← جدول انتقالات (Start→Current) يحافظ على مجموع كل علامة بداية، مع التصنيف من المصفوفة والانخفاضات إن وُجدت. إن كان الهدف مستحيلاً (لا Less لمن يبدأ B/B+) يُعرض السبب وأقرب بديل.
B24: المقترحات | C24: نتائج الحاسبتين مقترحات تخطيطية منفصلة تماماً عن النتائج الفعلية ولا تعدّلها.
B25: الواجهة والحماية
B26: الألوان | C26: أصفر + خط أزرق = إدخال · أبيض/أسود = صيغة. أحمر = Less · أصفر = Expected · أخضر = Better. ألوان الأحكام من جدول المفتاح.
B27: الحماية | C27: الأوراق محمية بلا كلمة مرور (مراجعة ← إلغاء حماية الورقة) لمنع كتابة فوق الصيغ بالخطأ؛ خلايا الإدخال مفتوحة.
B28: بيانات «مثال» | C28: ورقة مثال_Example بيانات مصطنعة. تظهر في التقارير فقط إذا اخترت «نعم» في Settings. ورقة Data فارغة (النتائج الفعلية).
B29: حدود معروفة
B30: لا رفع صور | C30: لا يوجد زر رفع صور: Excel لا يقرأ صور Go4Schools/Power BI بالصيغ. الإدخال يدوي (أو نسخ/لصق) في Data.
B31: بلا ماكرو | C31: كل شيء بالصيغ (xlsx). الحاسبتان بالصيغ لا Solver ولا ماكرو؛ قاعدة التوزيع في Target_Progress ترتيب أفضلية واضح وليست حلاً أمثل عالمياً.
B32: السعة | C32: Data تتسع 5000 سطر (مثال 800). للتوسع: انسخ آخر سطر في Data إلى الأسفل وعدّل نطاقات التجميع (تتطلب إلغاء الحماية).
B33: فلتر الصف في Dashboard | C33: يؤثر على البطاقات وعلى جدول الفترات، بينما جدول/رسوم «حسب الصف» تعرض كل الصفوف دائماً.
B34: رموز المواد | C34: Aa Arabic A · Ab Arabic B · Ia Islamic A · Ib Islamic B · Ua (الاسم غير مؤكد — عدّله في Settings). مستبعدة: Ft, Ss, Su, Pp, Pa, Re, Gs, Af, Ae (FS2 وY1). أضف أي رمز في Settings ثم الصفوف في Classes.
B35: افتراضات موثّقة | C35: مفتاح التقدم = مفتاح التحصيل مبدئياً · العام الدراسي 2026-27 من تاريخ الجدول · قراءة المصفوفة من صورة مائلة (راجع Progress_Matrix ثم Tests).
B37: خريطة الأوراق | Sheet map
B38: Dashboard | C38: اللوحة الرئيسية: بطاقات ومقارنة الفترات والرسوم
B39: Year_Panel | C39: لوحة لكل صف: أعداد ونسب وتقديرات حسب البلوك
B40: Teacher_Report | C40: نتائج كل معلم
B41: Data | C41: إدخال الأعداد المجمّعة (النتائج الفعلية)
B42: Target_Attain | C42: حاسبة مستهدف التحصيل
B43: Target_Progress | C43: حاسبة مستهدف التقدم
...

Sheet Dashboard
B1: لوحة تحليل نتائج الطلاب | Student Attainment & Progress Dashboard
B3: ="Year 2 – Year 13 · العام الدراسي "&Settings!C6&" · أعداد مجمّعة بلا أسماء طلاب · الفلاتر تؤثر على البطاقات والجداول والرسوم" -> Year 2 – Year 13 · العام الدراسي 2026-27 · أعداد مجمّعة بلا أسماء طلاب · الفلاتر تؤثر على البطاقات والجداول والرسوم
B4: الدليل | C4: اللوحة | D4: لوحة الصف | E4: المعلمون | F4: إدخال النتائج | G4: هدف التحصيل | H4: هدف التقدم | I4: الإعدادات | J4: المصفوفة | K4: الصفوف | L4: فحوص | M4: اختبارات
P5: معايير الفلاتر (مساعدة)
B6: المادة (Subject) | D6: الصف (Year) | F6: المعلم (Teacher) | H6: البلوك (Block) | J6: الفترة (Term) | L6: المجموعة (Group) | P6: =IF(B7="الكل (All)","*",B7) -> *
B7: الكل (All) | D7: الكل (All) | F7: الكل (All) | H7: الكل (All) | J7: Term 1 | L7: إجمالي الصف (All) | P7: =IF(D7="الكل (All)","*",D7) -> *
B8: =IF(Checks!$C$6>0,"⚠ توجد "&Checks!$C$6&" صفوف غير صالحة في Data (راجع عمود الحالة) — لا تدخل في الحساب. ","")&IF(Checks!$C$7>0,"⚠ تنبيهات اتساق: "&Checks!$C$7&" (ورقة Checks). ","")&IF(ExOn=1,"ℹ بيانات «مثال» مُدرجة في التقارير حالياً (Settings).","") | P8: =IF(F7="الكل (All)","*",F7) -> *
P9: =IF(H7="الكل (All)","*",H7) -> *
B10: التحصيل | Attainment — للفلاتر الحالية | P10: =J7 -> Term 1
B11: طلاب بنتائج Students with results | D11: At & Above | F11: Above | H11: حكم التحصيل Attainment rating | J11: Δ At & Above مقابل Baseline | L11: Δ Above مقابل Baseline | P11: =L7 -> إجمالي الصف (All)
B12: =$Q$13 -> 0 | D12: =IF($Q$13=0,"لا توجد بيانات",$Q$14/$Q$13) -> لا توجد بيانات | F12: =IF($Q$13=0,"لا توجد بيانات",$Q$15/$Q$13) -> لا توجد بيانات | H12: =IF($Q$13=0,"لا توجد بيانات",IF(ROUND($Q$14/$Q$13,10)<=KeyA_VW,"Very Weak",IF(ROUND($Q$14/$Q$13,10)<KeyA_Weak,"Weak",IF(ROUND($Q$15/$Q$13,10)<KeyA_Acc,"Acceptable",IF(ROUND($Q$15/$Q$13,10)<=KeyA_Good,"Good",IF(ROUND($Q$15/$Q$13,10)<KeyA_Out,"Very Good","Outstanding")))))) -> لا توجد بيانات | J12: =IF(OR($P$10="Baseline",$Q$13=0,$Q$16=0),"—",$Q$14/$Q$13-$Q$17/$Q$16) -> — | L12: =IF(OR($P$10="Baseline",$Q$13=0,$Q$16=0),"—",$Q$15/$Q$13-$Q$18/$Q$16) -> — | P12: قيم مساعدة (للقراءة فقط)
B13: =IF($Q$13=0,"لا توجد بيانات","غياب/بدون نتيجة مستبعد") -> لا توجد بيانات | D13: =IF($Q$13=0,"",$Q$14&" من "&$Q$13&" طالب") | F13: =IF($Q$13=0,"",$Q$15&" من "&$Q$13&" طالب") | H13: حسب المفتاح في Settings | J13: نقاط مئوية (الفترة المختارة − Baseline) | L13: نقاط مئوية (الفترة المختارة − Baseline) | P13: طلاب بنتائج | Q13: =(SUMIFS(Data!$Q$5:$Q$5004,Data!$B$5:$B$5004,$P$6,Data!$C$5:$C$5004,$P$8,Data!$D$5:$D$5004,$P$7,Data!$E$5:$E$5004,$P$9,Data!$F$5:$F$5004,$P$10,Data!$G$5:$G$5004,$P$11)+ExOn*SUMIFS(مثال_Example!$Q$5:$Q$804,مثال_Example!$B$5:$B$804,$P$6,مثال_Example!$C$5:$C$804,$P$8,مثال_Example!$D$5:$D$804,$P$7,مثال_Example!$E$5:$E$804,$P$9,مثال_Example!$F$5:$F$804,$P$10,مثال_Example!$G$5:$G$804,$P$11)) -> 0
P14: At & Above | Q14: =(SUMIFS(Data!$R$5:$R$5004,Data!$B$5:$B$5004,$P$6,Data!$C$5:$C$5004,$P$8,Data!$D$5:$D$5004,$P$7,Data!$E$5:$E$5004,$P$9,Data!$F$5:$F$5004,$P$10,Data!$G$5:$G$5004,$P$11)+ExOn*SUMIFS(مثال_Example!$R$5:$R$804,مثال_Example!$B$5:$B$804,$P$6,مثال_Example!$C$5:$C$804,$P$8,مثال_Example!$D$5:$D$804,$P$7,مثال_Example!$E$5:$E$804,$P$9,مثال_Example!$F$5:$F$804,$P$10,مثال_Example!$G$5:$G$804,$P$11)) -> 0
B15: التقدم | Progress — للفلاتر الحالية | P15: Above | Q15: =(SUMIFS(Data!$S$5:$S$5004,Data!$B$5:$B$5004,$P$6,Data!$C$5:$C$5004,$P$8,Data!$D$5:$D$5004,$P$7,Data!$E$5:$E$5004,$P$9,Data!$F$5:$F$5004,$P$10,Data!$G$5:$G$5004,$P$11)+ExOn*SUMIFS(مثال_Example!$S$5:$S$804,مثال_Example!$B$5:$B$804,$P$6,مثال_Example!$C$5:$C$804,$P$8,مثال_Example!$D$5:$D$804,$P$7,مثال_Example!$E$5:$E$804,$P$9,مثال_Example!$F$5:$F$804,$P$10,مثال_Example!$G$5:$G$804,$P$11)) -> 0
B16: حالات تقدم قابلة للتصنيف Progress cases | D16: Less Than Expected | F16: Expected | H16: Better Than Expected | J16: Expected & Better | L16: حكم التقدم Progress rating | P16: Baseline: بنتائج | Q16: =(SUMIFS(Data!$Q$5:$Q$5004,Data!$B$5:$B$5004,$P$6,Data!$C$5:$C$5004,$P$8,Data!$D$5:$D$5004,$P$7,Data!$E$5:$E$5004,$P$9,Data!$F$5:$F$5004,"Baseline",Data!$G$5:$G$5004,$P$11)+ExOn*SUMIFS(مثال_Example!$Q$5:$Q$804,مثال_Example!$B$5:$B$804,$P$6,مثال_Example!$C$5:$C$804,$P$8,مثال_Example!$D$5:$D$804,$P$7,مثال_Example!$E$5:$E$804,$P$9,مثال_Example!$F$5:$F$804,"Baseline",مثال_Example!$G$5:$G$804,$P$11)) -> 0
B17: =$Q$24 -> 0 | D17: =IF($Q$24=0,"لا توجد بيانات",$Q$19/$Q$24) -> لا توجد بيانات | F17: =IF($Q$24=0,"لا توجد بيانات",$Q$20/$Q$24) -> لا توجد بيانات | H17: =IF($Q$24=0,"لا توجد بيانات",$Q$21/$Q$24) -> لا توجد بيانات | J17: =IF($Q$24=0,"لا توجد بيانات",($Q$20+$Q$21)/$Q$24) -> لا توجد بيانات | L17: =IF($Q$24=0,"لا توجد بيانات",IF(ROUND(($Q$20+$Q$21)/$Q$24,10)<=KeyP_VW,"Very Weak",IF(ROUND(($Q$20+$Q$21)/$Q$24,10)<KeyP_Weak,"Weak",IF(ROUND($Q$21/$Q$24,10)<KeyP_Acc,"Acceptable",IF(ROUND($Q$21/$Q$24,10)<=KeyP_Good,"Good",IF(ROUND($Q$21/$Q$24,10)<KeyP_Out,"Very Good","Outstanding")))))) -> لا توجد بيانات | P17: Baseline: At | Q17: =(SUMIFS(Data!$R$5:$R$5004,Data!$B$5:$B$5004,$P$6,Data!$C$5:$C$5004,$P$8,Data!$D$5:$D$5004,$P$7,Data!$E$5:$E$5004,$P$9,Data!$F$5:$F$5004,"Baseline",Data!$G$5:$G$5004,$P$11)+ExOn*SUMIFS(مثال_Example!$R$5:$R$804,مثال_Example!$B$5:$B$804,$P$6,مثال_Example!$C$5:$C$804,$P$8,مثال_Example!$D$5:$D$804,$P$7,مثال_Example!$E$5:$E$804,$P$9,مثال_Example!$F$5:$F$804,"Baseline",مثال_Example!$G$5:$G$804,$P$11)) -> 0
B18: ="مستبعد: U "&$Q$22&" · بدون Start "&$Q$23 -> مستبعد: U 0 · بدون Start 0 | D18: =IF($Q$24=0,"",$Q$19&" طالب") | F18: =IF($Q$24=0,"",$Q$20&" طالب") | H18: =IF($Q$24=0,"",$Q$21&" طالب") | J18: =IF($Q$24=0,"",($Q$20+$Q$21)&" طالب") | L18: حسب مفتاح التقدم في Settings | P18: Baseline: Above | Q18: =(SUMIFS(Data!$S$5:$S$5004,Data!$B$5:$B$5004,$P$6,Data!$C$5:$C$5004,$P$8,Data!$D$5:$D$5004,$P$7,Data!$E$5:$E$5004,$P$9,Data!$F$5:$F$5004,"Baseline",Data!$G$5:$G$5004,$P$11)+ExOn*SUMIFS(مثال_Example!$S$5:$S$804,مثال_Example!$B$5:$B$804,$P$6,مثال_Example!$C$5:$C$804,$P$8,مثال_Example!$D$5:$D$804,$P$7,مثال_Example!$E$5:$E$804,$P$9,مثال_Example!$F$5:$F$804,"Baseline",مثال_Example!$G$5:$G$804,$P$11)) -> 0
P19: Less | Q19: =(SUMIFS(Data!$T$5:$T$5004,Data!$B$5:$B$5004,$P$6,Data!$C$5:$C$5004,$P$8,Data!$D$5:$D$5004,$P$7,Data!$E$5:$E$5004,$P$9,Data!$F$5:$F$5004,$P$10,Data!$G$5:$G$5004,$P$11)+ExOn*SUMIFS(مثال_Example!$T$5:$T$804,مثال_Example!$B$5:$B$804,$P$6,مثال_Example!$C$5:$C$804,$P$8,مثال_Example!$D$5:$D$804,$P$7,مثال_Example!$E$5:$E$804,$P$9,مثال_Example!$F$5:$F$804,$P$10,مثال_Example!$G$5:$G$804,$P$11)) -> 0
B20: الرسوم | Charts | P20: Expected | Q20: =(SUMIFS(Data!$U$5:$U$5004,Data!$B$5:$B$5004,$P$6,Data!$C$5:$C$5004,$P$8,Data!$D$5:$D$5004,$P$7,Data!$E$5:$E$5004,$P$9,Data!$F$5:$F$5004,$P$10,Data!$G$5:$G$5004,$P$11)+ExOn*SUMIFS(مثال_Example!$U$5:$U$804,مثال_Example!$B$5:$B$804,$P$6,مثال_Example!$C$5:$C$804,$P$8,مثال_Example!$D$5:$D$804,$P$7,مثال_Example!$E$5:$E$804,$P$9,مثال_Example!$F$5:$F$804,$P$10,مثال_Example!$G$5:$G$804,$P$11)) -> 0
P21: Better | Q21: =(SUMIFS(Data!$V$5:$V$5004,Data!$B$5:$B$5004,$P$6,Data!$C$5:$C$5004,$P$8,Data!$D$5:$D$5004,$P$7,Data!$E$5:$E$5004,$P$9,Data!$F$5:$F$5004,$P$10,Data!$G$5:$G$5004,$P$11)+ExOn*SUMIFS(مثال_Example!$V$5:$V$804,مثال_Example!$B$5:$B$804,$P$6,مثال_Example!$C$5:$C$804,$P$8,مثال_Example!$D$5:$D$804,$P$7,مثال_Example!$E$5:$E$804,$P$9,مثال_Example!$F$5:$F$804,$P$10,مثال_Example!$G$5:$G$804,$P$11)) -> 0
P22: U مستبعد | Q22: =(SUMIFS(Data!$W$5:$W$5004,Data!$B$5:$B$5004,$P$6,Data!$C$5:$C$5004,$P$8,Data!$D$5:$D$5004,$P$7,Data!$E$5:$E$5004,$P$9,Data!$F$5:$F$5004,$P$10,Data!$G$5:$G$5004,$P$11)+ExOn*SUMIFS(مثال_Example!$W$5:$W$804,مثال_Example!$B$5:$B$804,$P$6,مثال_Example!$C$5:$C$804,$P$8,مثال_Example!$D$5:$D$804,$P$7,مثال_Example!$E$5:$E$804,$P$9,مثال_Example!$F$5:$F$804,$P$10,مثال_Example!$G$5:$G$804,$P$11)) -> 0
P23: بدون Start | Q23: =(SUMIFS(Data!$X$5:$X$5004,Data!$B$5:$B$5004,$P$6,Data!$C$5:$C$5004,$P$8,Data!$D$5:$D$5004,$P$7,Data!$E$5:$E$5004,$P$9,Data!$F$5:$F$5004,$P$10,Data!$G$5:$G$5004,$P$11)+ExOn*SUMIFS(مثال_Example!$X$5:$X$804,مثال_Example!$B$5:$B$804,$P$6,مثال_Example!$C$5:$C$804,$P$8,مثال_Example!$D$5:$D$804,$P$7,مثال_Example!$E$5:$E$804,$P$9,مثال_Example!$F$5:$F$804,$P$10,مثال_Example!$G$5:$G$804,$P$11)) -> 0
P24: حالات التقدم | Q24: =$Q$19+$Q$20+$Q$21 -> 0
H70: مفتاح الأحكام | Rating key
H71: Outstanding | J71: At & Above ≥ 75% و Above ≥ 75%
H72: Very Good | J72: At & Above ≥ 75% و Above > 60% و < 75%
H73: Good | J73: At & Above ≥ 75% و Above من 50% إلى 60%
H74: Acceptable | J74: At & Above ≥ 75% و Above < 50%
H75: Weak | J75: At & Above بين 15% و 75% (أقل من 75%)
H76: Very Weak | J76: At & Above ≤ 15%
H77: Less Than Expected | J77: التصنيف يُؤخذ من مصفوفة التقدم (Progress_Matrix) بالبحث عن Start Point والدرجة الحالية. U وحالات بلا Start تُستبعد من التقدم وتُعرض أعدادها.
H78: Expected
H79: Better Than Expected
B93: المقارنة مع نقطة البداية حسب الفترة | By Term (Baseline → Term 3)
B94: الفترة Term | C94: طلاب بنتائج | D94: At & Above % | E94: Above % | F94: Δ At&Above مقابل BSL | G94: Δ Above مقابل BSL | H94: حالات تقدم | I94: Less % | J94: Expected % | K94: Better % | L94: Expected&Better % | M94: حكم التحصيل
B95: Baseline | C95: =(SUMIFS(Data!$Q$5:$Q$5004,Data!$B$5:$B$5004,$P$6,Data!$C$5:$C$5004,$P$8,Data!$D$5:$D$5004,$P$7,Data!$E$5:$E$5004,$P$9,Data!$F$5:$F$5004,$B95,Data!$G$5:$G$5004,$P$11)+ExOn*SUMIFS(مثال_Example!$Q$5:$Q$804,مثال_Example!$B$5:$B$804,$P$6,مثال_Example!$C$5:$C$804,$P$8,مثال_Example!$D$5:$D$804,$P$7,مثال_Example!$E$5:$E$804,$P$9,مثال_Example!$F$5:$F$804,$B95,مثال_Example!$G$5:$G$804,$P$11)) -> 0 | D95: =IF($C95=0,"—",(SUMIFS(Data!$R$5:$R$5004,Data!$B$5:$B$5004,$P$6,Data!$C$5:$C$5004,$P$8,Data!$D$5:$D$5004,$P$7,Data!$E$5:$E$5004,$P$9,Data!$F$5:$F$5004,$B95,Data!$G$5:$G$5004,$P$11)+ExOn*SUMIFS(مثال_Example!$R$5:$R$804,مثال_Example!$B$5:$B$804,$P$6,مثال_Example!$C$5:$C$804,$P$8,مثال_Example!$D$5:$D$804,$P$7,مثال_Example!$E$5:$E$804,$P$9,مثال_Example!$F$5:$F$804,$B95,مثال_Example!$G$5:$G$804,$P$11))/$C95) -> — | E95: =IF($C95=0,"—",(SUMIFS(Data!$S$5:$S$5004,Data!$B$5:$B$5004,$P$6,Data!$C$5:$C$5004,$P$8,Data!$D$5:$D$5004,$P$7,Data!$E$5:$E$5004,$P$9,Data!$F$5:$F$5004,$B95,Data!$G$5:$G$5004,$P$11)+ExOn*SUMIFS(مثال_Example!$S$5:$S$804,مثال_Example!$B$5:$B$804,$P$6,مثال_Example!$C$5:$C$804,$P$8,مثال_Example!$D$5:$D$804,$P$7,مثال_Example!$E$5:$E$804,$P$9,مثال_Example!$F$5:$F$804,$B95,مثال_Example!$G$5:$G$804,$P$11))/$C95) -> — | F95: =IF(OR($B95="Baseline",NOT(ISNUMBER(D95)),NOT(ISNUMBER(D$95))),"—",D95-D$95) -> — | G95: =IF(OR($B95="Baseline",NOT(ISNUMBER(E95)),NOT(ISNUMBER(E$95))),"—",E95-E$95) -> — | H95: =(SUMIFS(Data!$T$5:$T$5004,Data!$B$5:$B$5004,$P$6,Data!$C$5:$C$5004,$P$8,Data!$D$5:$D$5004,$P$7,Data!$E$5:$E$5004,$P$9,Data!$F$5:$F$5004,$B95,Data!$G$5:$G$5004,$P$11)+ExOn*SUMIFS(مثال_Example!$T$5:$T$804,مثال_Example!$B$5:$B$804,$P$6,مثال_Example!$C$5:$C$804,$P$8,مثال_Example!$D$5:$D$804,$P$7,مثال_Example!$E$5:$E$804,$P$9,مثال_Example!$F$5:$F$804,$B95,مثال_Example!$G$5:$G$804,$P$11))+(SUMIFS(Data!$U$5:$U$5004,Data!$B$5:$B$5004,$P$6,Data!$C$5:$C$5004,$P$8,Data!$D$5:$D$5004,$P$7,Data!$E$5:$E$5004,$P$9,Data!$F$5:$F$5004,$B95,Data!$G$5:$G$5004,$P$11)+ExOn*SUMIFS(مثال_Example!$U$5:$U$804,مثال_Example!$B$5:$B$804,$P$6,مثال_Example!$C$5:$C$804,$P$8,مثال_Example!$D$5:$D$804,$P$7,مثال_Example!$E$5:$E$804,$P$9,مثال_Example!$F$5:$F$804,$B95,مثال_Example!$G$5:$G$804,$P$11))+(SUMIFS(Data!$V$5:$V$5004,Data!$B$5:$B$5004,$P$6,Data!$C$5:$C$5004,$P$8,Data!$D$5:$D$5004,$P$7,Data!$E$5:$E$5004,$P$9,Data!$F$5:$F$5004,$B95,Data!$G$5:$G$5004,$P$11)+ExOn*SUMIFS(مثال_Example!$V$5:$V$804,مثال_Example!$B$5:$B$804,$P$6,مثال_Example!$C$5:$C$804,$P$8,مثال_Example!$D$5:$D$804,$P$7,مثال_Example!$E$5:$E$804,$P$9,مثال_Example!$F$5:$F$804,$B95,مثال_Example!$G$5:$G$804,$P$11)) -> 0 | I95: =IF($H95=0,"—",(SUMIFS(Data!$T$5:$T$5004,Data!$B$5:$B$5004,$P$6,Data!$C$5:$C$5004,$P$8,Data!$D$5:$D$5004,$P$7,Data!$E$5:$E$5004,$P$9,Data!$F$5:$F$5004,$B95,Data!$G$5:$G$5004,$P$11)+ExOn*SUMIFS(مثال_Example!$T$5:$T$804,مثال_Example!$B$5:$B$804,$P$6,مثال_Example!$C$5:$C$804,$P$8,مثال_Example!$D$5:$D$804,$P$7,مثال_Example!$E$5:$E$804,$P$9,مثال_Example!$F$5:$F$804,$B95,مثال_Example!$G$5:$G$804,$P$11))/$H95) -> — | J95: =IF($H95=0,"—",(SUMIFS(Data!$U$5:$U$5004,Data!$B$5:$B$5004,$P$6,Data!$C$5:$C$5004,$P$8,Data!$D$5:$D$5004,$P$7,Data!$E$5:$E$5004,$P$9,Data!$F$5:$F$5004,$B95,Data!$G$5:$G$5004,$P$11)+ExOn*SUMIFS(مثال_Example!$U$5:$U$804,مثال_Example!$B$5:$B$804,$P$6,مثال_Example!$C$5:$C$804,$P$8,مثال_Example!$D$5:$D$804,$P$7,مثال_Example!$E$5:$E$804,$P$9,مثال_Example!$F$5:$F$804,$B95,مثال_Example!$G$5:$G$804,$P$11))/$H95) -> — | K95: =IF($H95=0,"—",(SUMIFS(Data!$V$5:$V$5004,Data!$B$5:$B$5004,$P$6,Data!$C$5:$C$5004,$P$8,Data!$D$5:$D$5004,$P$7,Data!$E$5:$E$5004,$P$9,Data!$F$5:$F$5004,$B95,Data!$G$5:$G$5004,$P$11)+ExOn*SUMIFS(مثال_Example!$V$5:$V$804,مثال_Example!$B$5:$B$804,$P$6,مثال_Example!$C$5:$C$804,$P$8,مثال_Example!$D$5:$D$804,$P$7,مثال_Example!$E$5:$E$804,$P$9,مثال_Example!$F$5:$F$804,$B95,مثال_Example!$G$5:$G$804,$P$11))/$H95) -> — | L95: =IF($H95=0,"—",((SUMIFS(Data!$U$5:$U$5004,Data!$B$5:$B$5004,$P$6,Data!$C$5:$C$5004,$P$8,Data!$D$5:$D$5004,$P$7,Data!$E$5:$E$5004,$P$9,Data!$F$5:$F$5004,$B95,Data!$G$5:$G$5004,$P$11)+ExOn*SUMIFS(مثال_Example!$U$5:$U$804,مثال_Example!$B$5:$B$804,$P$6,مثال_Example!$C$5:$C$804,$P$8,مثال_Example!$D$5:$D$804,$P$7,مثال_Example!$E$5:$E$804,$P$9,مثال_Example!$F$5:$F$804,$B95,مثال_Example!$G$5:$G$804,$P$11))+(SUMIFS(Data!$V$5:$V$5004,Data!$B$5:$B$5004,$P$6,Data!$C$5:$C$5004,$P$8,Data!$D$5:$D$5004,$P$7,Data!$E$5:$E$5004,$P$9,Data!$F$5:$F$5004,$B95,Data!$G$5:$G$5004,$P$11)+ExOn*SUMIFS(مثال_Example!$V$5:$V$804,مثال_Example!$B$5:$B$804,$P$6,مثال_Example!$C$5:$C$804,$P$8,مثال_Example!$D$5:$D$804,$P$7,مثال_Example!$E$5:$E$804,$P$9,مثال_Example!$F$5:$F$804,$B95,مثال_Example!$G$5:$G$804,$P$11)))/$H95) -> — | M95: =IF($C95=0,"لا توجد بيانات",IF(ROUND(IF(ISNUMBER(D95),D95,0),10)<=KeyA_VW,"Very Weak",IF(ROUND(IF(ISNUMBER(D95),D95,0),10)<KeyA_Weak,"Weak",IF(ROUND(IF(ISNUMBER(E95),E95,0),10)<KeyA_Acc,"Acceptable",IF(ROUND(IF(ISNUMBER(E95),E95,0),10)<=KeyA_Good,"Good",IF(ROUND(IF(ISNUMBER(E95),E95,0),10)<KeyA_Out,"Very Good","Outstanding")))))) -> لا توجد بيانات
B96: Term 1 | C96: =(SUMIFS(Data!$Q$5:$Q$5004,Data!$B$5:$B$5004,$P$6,Data!$C$5:$C$5004,$P$8,Data!$D$5:$D$5004,$P$7,Data!$E$5:$E$5004,$P$9,Data!$F$5:$F$5004,$B96,Data!$G$5:$G$5004,$P$11)+ExOn*SUMIFS(مثال_Example!$Q$5:$Q$804,مثال_Example!$B$5:$B$804,$P$6,مثال_Example!$C$5:$C$804,$P$8,مثال_Example!$D$5:$D$804,$P$7,مثال_Example!$E$5:$E$804,$P$9,مثال_Example!$F$5:$F$804,$B96,مثال_Example!$G$5:$G$804,$P$11)) -> 0 | D96: =IF($C96=0,"—",(SUMIFS(Data!$R$5:$R$5004,Data!$B$5:$B$5004,$P$6,Data!$C$5:$C$5004,$P$8,Data!$D$5:$D$5004,$P$7,Data!$E$5:$E$5004,$P$9,Data!$F$5:$F$5004,$B96,Data!$G$5:$G$5004,$P$11)+ExOn*SUMIFS(مثال_Example!$R$5:$R$804,مثال_Example!$B$5:$B$804,$P$6,مثال_Example!$C$5:$C$804,$P$8,مثال_Example!$D$5:$D$804,$P$7,مثال_Example!$E$5:$E$804,$P$9,مثال_Example!$F$5:$F$804,$B96,مثال_Example!$G$5:$G$804,$P$11))/$C96) -> — | E96: =IF($C96=0,"—",(SUMIFS(Data!$S$5:$S$5004,Data!$B$5:$B$5004,$P$6,Data!$C$5:$C$5004,$P$8,Data!$D$5:$D$5004,$P$7,Data!$E$5:$E$5004,$P$9,Data!$F$5:$F$5004,$B96,Data!$G$5:$G$5004,$P$11)+ExOn*SUMIFS(مثال_Example!$S$5:$S$804,مثال_Example!$B$5:$B$804,$P$6,مثال_Example!$C$5:$C$804,$P$8,مثال_Example!$D$5:$D$804,$P$7,مثال_Example!$E$5:$E$804,$P$9,مثال_Example!$F$5:$F$804,$B96,مثال_Example!$G$5:$G$804,$P$11))/$C96) -> — | F96: =IF(OR($B96="Baseline",NOT(ISNUMBER(D96)),NOT(ISNUMBER(D$95))),"—",D96-D$95) -> — | G96: =IF(OR($B96="Baseline",NOT(ISNUMBER(E96)),NOT(ISNUMBER(E$95))),"—",E96-E$95) -> — | H96: =(SUMIFS(Data!$T$5:$T$5004,Data!$B$5:$B$5004,$P$6,Data!$C$5:$C$5004,$P$8,Data!$D$5:$D$5004,$P$7,Data!$E$5:$E$5004,$P$9,Data!$F$5:$F$5004,$B96,Data!$G$5:$G$5004,$P$11)+ExOn*SUMIFS(مثال_Example!$T$5:$T$804,مثال_Example!$B$5:$B$804,$P$6,مثال_Example!$C$5:$C$804,$P$8,مثال_Example!$D$5:$D$804,$P$7,مثال_Example!$E$5:$E$804,$P$9,مثال_Example!$F$5:$F$804,$B96,مثال_Example!$G$5:$G$804,$P$11))+(SUMIFS(Data!$U$5:$U$5004,Data!$B$5:$B$5004,$P$6,Data!$C$5:$C$5004,$P$8,Data!$D$5:$D$5004,$P$7,Data!$E$5:$E$5004,$P$9,Data!$F$5:$F$5004,$B96,Data!$G$5:$G$5004,$P$11)+ExOn*SUMIFS(مثال_Example!$U$5:$U$804,مثال_Example!$B$5:$B$804,$P$6,مثال_Example!$C$5:$C$804,$P$8,مثال_Example!$D$5:$D$804,$P$7,مثال_Example!$E$5:$E$804,$P$9,مثال_Example!$F$5:$F$804,$B96,مثال_Example!$G$5:$G$804,$P$11))+(SUMIFS(Data!$V$5:$V$5004,Data!$B$5:$B$5004,$P$6,Data!$C$5:$C$5004,$P$8,Data!$D$5:$D$5004,$P$7,Data!$E$5:$E$5004,$P$9,Data!$F$5:$F$5004,$B96,Data!$G$5:$G$5004,$P$11)+ExOn*SUMIFS(مثال_Example!$V$5:$V$804,مثال_Example!$B$5:$B$804,$P$6,مثال_Example!$C$5:$C$804,$P$8,مثال_Example!$D$5:$D$804,$P$7,مثال_Example!$E$5:$E$804,$P$9,مثال_Example!$F$5:$F$804,$B96,مثال_Example!$G$5:$G$804,$P$11)) -> 0 | I96: =IF($H96=0,"—",(SUMIFS(Data!$T$5:$T$5004,Data!$B$5:$B$5004,$P$6,Data!$C$5:$C$5004,$P$8,Data!$D$5:$D$5004,$P$7,Data!$E$5:$E$5004,$P$9,Data!$F$5:$F$5004,$B96,Data!$G$5:$G$5004,$P$11)+ExOn*SUMIFS(مثال_Example!$T$5:$T$804,مثال_Example!$B$5:$B$804,$P$6,مثال_Example!$C$5:$C$804,$P$8,مثال_Example!$D$5:$D$804,$P$7,مثال_Example!$E$5:$E$804,$P$9,مثال_Example!$F$5:$F$804,$B96,مثال_Example!$G$5:$G$804,$P$11))/$H96) -> — | J96: =IF($H96=0,"—",(SUMIFS(Data!$U$5:$U$5004,Data!$B$5:$B$5004,$P$6,Data!$C$5:$C$5004,$P$8,Data!$D$5:$D$5004,$P$7,Data!$E$5:$E$5004,$P$9,Data!$F$5:$F$5004,$B96,Data!$G$5:$G$5004,$P$11)+ExOn*SUMIFS(مثال_Example!$U$5:$U$804,مثال_Example!$B$5:$B$804,$P$6,مثال_Example!$C$5:$C$804,$P$8,مثال_Example!$D$5:$D$804,$P$7,مثال_Example!$E$5:$E$804,$P$9,مثال_Example!$F$5:$F$804,$B96,مثال_Example!$G$5:$G$804,$P$11))/$H96) -> — | K96: =IF($H96=0,"—",(SUMIFS(Data!$V$5:$V$5004,Data!$B$5:$B$5004,$P$6,Data!$C$5:$C$5004,$P$8,Data!$D$5:$D$5004,$P$7,Data!$E$5:$E$5004,$P$9,Data!$F$5:$F$5004,$B96,Data!$G$5:$G$5004,$P$11)+ExOn*SUMIFS(مثال_Example!$V$5:$V$804,مثال_Example!$B$5:$B$804,$P$6,مثال_Example!$C$5:$C$804,$P$8,مثال_Example!$D$5:$D$804,$P$7,مثال_Example!$E$5:$E$804,$P$9,مثال_Example!$F$5:$F$804,$B96,مثال_Example!$G$5:$G$804,$P$11))/$H96) -> — | L96: =IF($H96=0,"—",((SUMIFS(Data!$U$5:$U$5004,Data!$B$5:$B$5004,$P$6,Data!$C$5:$C$5004,$P$8,Data!$D$5:$D$5004,$P$7,Data!$E$5:$E$5004,$P$9,Data!$F$5:$F$5004,$B96,Data!$G$5:$G$5004,$P$11)+ExOn*SUMIFS(مثال_Example!$U$5:$U$804,مثال_Example!$B$5:$B$804,$P$6,مثال_Example!$C$5:$C$804,$P$8,مثال_Example!$D$5:$D$804,$P$7,مثال_Example!$E$5:$E$804,$P$9,مثال_Example!$F$5:$F$804,$B96,مثال_Example!$G$5:$G$804,$P$11))+(SUMIFS(Data!$V$5:$V$5004,Data!$B$5:$B$5004,$P$6,Data!$C$5:$C$5004,$P$8,Data!$D$5:$D$5004,$P$7,Data!$E$5:$E$5004,$P$9,Data!$F$5:$F$5004,$B96,Data!$G$5:$G$5004,$P$11)+ExOn*SUMIFS(مثال_Example!$V$5:$V$804,مثال_Example!$B$5:$B$804,$P$6,مثال_Example!$C$5:$C$804,$P$8,مثال_Example!$D$5:$D$804,$P$7,مثال_Example!$E$5:$E$804,$P$9,مثال_Example!$F$5:$F$804,$B96,مثال_Example!$G$5:$G$804,$P$11)))/$H96) -> — | M96: =IF($C96=0,"لا توجد بيانات",IF(ROUND(IF(ISNUMBER(D96),D96,0),10)<=KeyA_VW,"Very Weak",IF(ROUND(IF(ISNUMBER(D96),D96,0),10)<KeyA_Weak,"Weak",IF(ROUND(IF(ISNUMBER(E96),E96,0),10)<KeyA_Acc,"Acceptable",IF(ROUND(IF(ISNUMBER(E96),E96,0),10)<=KeyA_Good,"Good",IF(ROUND(IF(ISNUMBER(E96),E96,0),10)<KeyA_Out,"Very Good","Outstanding")))))) -> لا توجد بيانات
B97: Term 2 | C97: =(SUMIFS(Data!$Q$5:$Q$5004,Data!$B$5:$B$5004,$P$6,Data!$C$5:$C$5004,$P$8,Data!$D$5:$D$5004,$P$7,Data!$E$5:$E$5004,$P$9,Data!$F$5:$F$5004,$B97,Data!$G$5:$G$5004,$P$11)+ExOn*SUMIFS(مثال_Example!$Q$5:$Q$804,مثال_Example!$B$5:$B$804,$P$6,مثال_Example!$C$5:$C$804,$P$8,مثال_Example!$D$5:$D$804,$P$7,مثال_Example!$E$5:$E$804,$P$9,مثال_Example!$F$5:$F$804,$B97,مثال_Example!$G$5:$G$804,$P$11)) -> 0 | D97: =IF($C97=0,"—",(SUMIFS(Data!$R$5:$R$5004,Data!$B$5:$B$5004,$P$6,Data!$C$5:$C$5004,$P$8,Data!$D$5:$D$5004,$P$7,Data!$E$5:$E$5004,$P$9,Data!$F$5:$F$5004,$B97,Data!$G$5:$G$5004,$P$11)+ExOn*SUMIFS(مثال_Example!$R$5:$R$804,مثال_Example!$B$5:$B$804,$P$6,مثال_Example!$C$5:$C$804,$P$8,مثال_Example!$D$5:$D$804,$P$7,مثال_Example!$E$5:$E$804,$P$9,مثال_Example!$F$5:$F$804,$B97,مثال_Example!$G$5:$G$804,$P$11))/$C97) -> — | E97: =IF($C97=0,"—",(SUMIFS(Data!$S$5:$S$5004,Data!$B$5:$B$5004,$P$6,Data!$C$5:$C$5004,$P$8,Data!$D$5:$D$5004,$P$7,Data!$E$5:$E$5004,$P$9,Data!$F$5:$F$5004,$B97,Data!$G$5:$G$5004,$P$11)+ExOn*SUMIFS(مثال_Example!$S$5:$S$804,مثال_Example!$B$5:$B$804,$P$6,مثال_Example!$C$5:$C$804,$P$8,مثال_Example!$D$5:$D$804,$P$7,مثال_Example!$E$5:$E$804,$P$9,مثال_Example!$F$5:$F$804,$B97,مثال_Example!$G$5:$G$804,$P$11))/$C97) -> — | F97: =IF(OR($B97="Baseline",NOT(ISNUMBER(D97)),NOT(ISNUMBER(D$95))),"—",D97-D$95) -> — | G97: =IF(OR($B97="Baseline",NOT(ISNUMBER(E97)),NOT(ISNUMBER(E$95))),"—",E97-E$95) -> — | H97: =(SUMIFS(Data!$T$5:$T$5004,Data!$B$5:$B$5004,$P$6,Data!$C$5:$C$5004,$P$8,Data!$D$5:$D$5004,$P$7,Data!$E$5:$E$5004,$P$9,Data!$F$5:$F$5004,$B97,Data!$G$5:$G$5004,$P$11)+ExOn*SUMIFS(مثال_Example!$T$5:$T$804,مثال_Example!$B$5:$B$804,$P$6,مثال_Example!$C$5:$C$804,$P$8,مثال_Example!$D$5:$D$804,$P$7,مثال_Example!$E$5:$E$804,$P$9,مثال_Example!$F$5:$F$804,$B97,مثال_Example!$G$5:$G$804,$P$11))+(SUMIFS(Data!$U$5:$U$5004,Data!$B$5:$B$5004,$P$6,Data!$C$5:$C$5004,$P$8,Data!$D$5:$D$5004,$P$7,Data!$E$5:$E$5004,$P$9,Data!$F$5:$F$5004,$B97,Data!$G$5:$G$5004,$P$11)+ExOn*SUMIFS(مثال_Example!$U$5:$U$804,مثال_Example!$B$5:$B$804,$P$6,مثال_Example!$C$5:$C$804,$P$8,مثال_Example!$D$5:$D$804,$P$7,مثال_Example!$E$5:$E$804,$P$9,مثال_Example!$F$5:$F$804,$B97,مثال_Example!$G$5:$G$804,$P$11))+(SUMIFS(Data!$V$5:$V$5004,Data!$B$5:$B$5004,$P$6,Data!$C$5:$C$5004,$P$8,Data!$D$5:$D$5004,$P$7,Data!$E$5:$E$5004,$P$9,Data!$F$5:$F$5004,$B97,Data!$G$5:$G$5004,$P$11)+ExOn*SUMIFS(مثال_Example!$V$5:$V$804,مثال_Example!$B$5:$B$804,$P$6,مثال_Example!$C$5:$C$804,$P$8,مثال_Example!$D$5:$D$804,$P$7,مثال_Example!$E$5:$E$804,$P$9,مثال_Example!$F$5:$F$804,$B97,مثال_Example!$G$5:$G$804,$P$11)) -> 0 | I97: =IF($H97=0,"—",(SUMIFS(Data!$T$5:$T$5004,Data!$B$5:$B$5004,$P$6,Data!$C$5:$C$5004,$P$8,Data!$D$5:$D$5004,$P$7,Data!$E$5:$E$5004,$P$9,Data!$F$5:$F$5004,$B97,Data!$G$5:$G$5004,$P$11)+ExOn*SUMIFS(مثال_Example!$T$5:$T$804,مثال_Example!$B$5:$B$804,$P$6,مثال_Example!$C$5:$C$804,$P$8,مثال_Example!$D$5:$D$804,$P$7,مثال_Example!$E$5:$E$804,$P$9,مثال_Example!$F$5:$F$804,$B97,مثال_Example!$G$5:$G$804,$P$11))/$H97) -> — | J97: =IF($H97=0,"—",(SUMIFS(Data!$U$5:$U$5004,Data!$B$5:$B$5004,$P$6,Data!$C$5:$C$5004,$P$8,Data!$D$5:$D$5004,$P$7,Data!$E$5:$E$5004,$P$9,Data!$F$5:$F$5004,$B97,Data!$G$5:$G$5004,$P$11)+ExOn*SUMIFS(مثال_Example!$U$5:$U$804,مثال_Example!$B$5:$B$804,$P$6,مثال_Example!$C$5:$C$804,$P$8,مثال_Example!$D$5:$D$804,$P$7,مثال_Example!$E$5:$E$804,$P$9,مثال_Example!$F$5:$F$804,$B97,مثال_Example!$G$5:$G$804,$P$11))/$H97) -> — | K97: =IF($H97=0,"—",(SUMIFS(Data!$V$5:$V$5004,Data!$B$5:$B$5004,$P$6,Data!$C$5:$C$5004,$P$8,Data!$D$5:$D$5004,$P$7,Data!$E$5:$E$5004,$P$9,Data!$F$5:$F$5004,$B97,Data!$G$5:$G$5004,$P$11)+ExOn*SUMIFS(مثال_Example!$V$5:$V$804,مثال_Example!$B$5:$B$804,$P$6,مثال_Example!$C$5:$C$804,$P$8,مثال_Example!$D$5:$D$804,$P$7,مثال_Example!$E$5:$E$804,$P$9,مثال_Example!$F$5:$F$804,$B97,مثال_Example!$G$5:$G$804,$P$11))/$H97) -> — | L97: =IF($H97=0,"—",((SUMIFS(Data!$U$5:$U$5004,Data!$B$5:$B$5004,$P$6,Data!$C$5:$C$5004,$P$8,Data!$D$5:$D$5004,$P$7,Data!$E$5:$E$5004,$P$9,Data!$F$5:$F$5004,$B97,Data!$G$5:$G$5004,$P$11)+ExOn*SUMIFS(مثال_Example!$U$5:$U$804,مثال_Example!$B$5:$B$804,$P$6,مثال_Example!$C$5:$C$804,$P$8,مثال_Example!$D$5:$D$804,$P$7,مثال_Example!$E$5:$E$804,$P$9,مثال_Example!$F$5:$F$804,$B97,مثال_Example!$G$5:$G$804,$P$11))+(SUMIFS(Data!$V$5:$V$5004,Data!$B$5:$B$5004,$P$6,Data!$C$5:$C$5004,$P$8,Data!$D$5:$D$5004,$P$7,Data!$E$5:$E$5004,$P$9,Data!$F$5:$F$5004,$B97,Data!$G$5:$G$5004,$P$11)+ExOn*SUMIFS(مثال_Example!$V$5:$V$804,مثال_Example!$B$5:$B$804,$P$6,مثال_Example!$C$5:$C$804,$P$8,مثال_Example!$D$5:$D$804,$P$7,مثال_Example!$E$5:$E$804,$P$9,مثال_Example!$F$5:$F$804,$B97,مثال_Example!$G$5:$G$804,$P$11)))/$H97) -> — | M97: =IF($C97=0,"لا توجد بيانات",IF(ROUND(IF(ISNUMBER(D97),D97,0),10)<=KeyA_VW,"Very Weak",IF(ROUND(IF(ISNUMBER(D97),D97,0),10)<KeyA_Weak,"Weak",IF(ROUND(IF(ISNUMBER(E97),E97,0),10)<KeyA_Acc,"Acceptable",IF(ROUND(IF(ISNUMBER(E97),E97,0),10)<=KeyA_Good,"Good",IF(ROUND(IF(ISNUMBER(E97),E97,0),10)<KeyA_Out,"Very Good","Outstanding")))))) -> لا توجد بيانات
B98: Term 3 | C98: =(SUMIFS(Data!$Q$5:$Q$5004,Data!$B$5:$B$5004,$P$6,Data!$C$5:$C$5004,$P$8,Data!$D$5:$D$5004,$P$7,Data!$E$5:$E$5004,$P$9,Data!$F$5:$F$5004,$B98,Data!$G$5:$G$5004,$P$11)+ExOn*SUMIFS(مثال_Example!$Q$5:$Q$804,مثال_Example!$B$5:$B$804,$P$6,مثال_Example!$C$5:$C$804,$P$8,مثال_Example!$D$5:$D$804,$P$7,مثال_Example!$E$5:$E$804,$P$9,مثال_Example!$F$5:$F$804,$B98,مثال_Example!$G$5:$G$804,$P$11)) -> 0 | D98: =IF($C98=0,"—",(SUMIFS(Data!$R$5:$R$5004,Data!$B$5:$B$5004,$P$6,Data!$C$5:$C$5004,$P$8,Data!$D$5:$D$5004,$P$7,Data!$E$5:$E$5004,$P$9,Data!$F$5:$F$5004,$B98,Data!$G$5:$G$5004,$P$11)+ExOn*SUMIFS(مثال_Example!$R$5:$R$804,مثال_Example!$B$5:$B$804,$P$6,مثال_Example!$C$5:$C$804,$P$8,مثال_Example!$D$5:$D$804,$P$7,مثال_Example!$E$5:$E$804,$P$9,مثال_Example!$F$5:$F$804,$B98,مثال_Example!$G$5:$G$804,$P$11))/$C98) -> — | E98: =IF($C98=0,"—",(SUMIFS(Data!$S$5:$S$5004,Data!$B$5:$B$5004,$P$6,Data!$C$5:$C$5004,$P$8,Data!$D$5:$D$5004,$P$7,Data!$E$5:$E$5004,$P$9,Data!$F$5:$F$5004,$B98,Data!$G$5:$G$5004,$P$11)+ExOn*SUMIFS(مثال_Example!$S$5:$S$804,مثال_Example!$B$5:$B$804,$P$6,مثال_Example!$C$5:$C$804,$P$8,مثال_Example!$D$5:$D$804,$P$7,مثال_Example!$E$5:$E$804,$P$9,مثال_Example!$F$5:$F$804,$B98,مثال_Example!$G$5:$G$804,$P$11))/$C98) -> — | F98: =IF(OR($B98="Baseline",NOT(ISNUMBER(D98)),NOT(ISNUMBER(D$95))),"—",D98-D$95) -> — | G98: =IF(OR($B98="Baseline",NOT(ISNUMBER(E98)),NOT(ISNUMBER(E$95))),"—",E98-E$95) -> — | H98: =(SUMIFS(Data!$T$5:$T$5004,Data!$B$5:$B$5004,$P$6,Data!$C$5:$C$5004,$P$8,Data!$D$5:$D$5004,$P$7,Data!$E$5:$E$5004,$P$9,Data!$F$5:$F$5004,$B98,Data!$G$5:$G$5004,$P$11)+ExOn*SUMIFS(مثال_Example!$T$5:$T$804,مثال_Example!$B$5:$B$804,$P$6,مثال_Example!$C$5:$C$804,$P$8,مثال_Example!$D$5:$D$804,$P$7,مثال_Example!$E$5:$E$804,$P$9,مثال_Example!$F$5:$F$804,$B98,مثال_Example!$G$5:$G$804,$P$11))+(SUMIFS(Data!$U$5:$U$5004,Data!$B$5:$B$5004,$P$6,Data!$C$5:$C$5004,$P$8,Data!$D$5:$D$5004,$P$7,Data!$E$5:$E$5004,$P$9,Data!$F$5:$F$5004,$B98,Data!$G$5:$G$5004,$P$11)+ExOn*SUMIFS(مثال_Example!$U$5:$U$804,مثال_Example!$B$5:$B$804,$P$6,مثال_Example!$C$5:$C$804,$P$8,مثال_Example!$D$5:$D$804,$P$7,مثال_Example!$E$5:$E$804,$P$9,مثال_Example!$F$5:$F$804,$B98,مثال_Example!$G$5:$G$804,$P$11))+(SUMIFS(Data!$V$5:$V$5004,Data!$B$5:$B$5004,$P$6,Data!$C$5:$C$5004,$P$8,Data!$D$5:$D$5004,$P$7,Data!$E$5:$E$5004,$P$9,Data!$F$5:$F$5004,$B98,Data!$G$5:$G$5004,$P$11)+ExOn*SUMIFS(مثال_Example!$V$5:$V$804,مثال_Example!$B$5:$B$804,$P$6,مثال_Example!$C$5:$C$804,$P$8,مثال_Example!$D$5:$D$804,$P$7,مثال_Example!$E$5:$E$804,$P$9,مثال_Example!$F$5:$F$804,$B98,مثال_Example!$G$5:$G$804,$P$11)) -> 0 | I98: =IF($H98=0,"—",(SUMIFS(Data!$T$5:$T$5004,Data!$B$5:$B$5004,$P$6,Data!$C$5:$C$5004,$P$8,Data!$D$5:$D$5004,$P$7,Data!$E$5:$E$5004,$P$9,Data!$F$5:$F$5004,$B98,Data!$G$5:$G$5004,$P$11)+ExOn*SUMIFS(مثال_Example!$T$5:$T$804,مثال_Example!$B$5:$B$804,$P$6,مثال_Example!$C$5:$C$804,$P$8,مثال_Example!$D$5:$D$804,$P$7,مثال_Example!$E$5:$E$804,$P$9,مثال_Example!$F$5:$F$804,$B98,مثال_Example!$G$5:$G$804,$P$11))/$H98) -> — | J98: =IF($H98=0,"—",(SUMIFS(Data!$U$5:$U$5004,Data!$B$5:$B$5004,$P$6,Data!$C$5:$C$5004,$P$8,Data!$D$5:$D$5004,$P$7,Data!$E$5:$E$5004,$P$9,Data!$F$5:$F$5004,$B98,Data!$G$5:$G$5004,$P$11)+ExOn*SUMIFS(مثال_Example!$U$5:$U$804,مثال_Example!$B$5:$B$804,$P$6,مثال_Example!$C$5:$C$804,$P$8,مثال_Example!$D$5:$D$804,$P$7,مثال_Example!$E$5:$E$804,$P$9,مثال_Example!$F$5:$F$804,$B98,مثال_Example!$G$5:$G$804,$P$11))/$H98) -> — | K98: =IF($H98=0,"—",(SUMIFS(Data!$V$5:$V$5004,Data!$B$5:$B$5004,$P$6,Data!$C$5:$C$5004,$P$8,Data!$D$5:$D$5004,$P$7,Data!$E$5:$E$5004,$P$9,Data!$F$5:$F$5004,$B98,Data!$G$5:$G$5004,$P$11)+ExOn*SUMIFS(مثال_Example!$V$5:$V$804,مثال_Example!$B$5:$B$804,$P$6,مثال_Example!$C$5:$C$804,$P$8,مثال_Example!$D$5:$D$804,$P$7,مثال_Example!$E$5:$E$804,$P$9,مثال_Example!$F$5:$F$804,$B98,مثال_Example!$G$5:$G$804,$P$11))/$H98) -> — | L98: =IF($H98=0,"—",((SUMIFS(Data!$U$5:$U$5004,Data!$B$5:$B$5004,$P$6,Data!$C$5:$C$5004,$P$8,Data!$D$5:$D$5004,$P$7,Data!$E$5:$E$5004,$P$9,Data!$F$5:$F$5004,$B98,Data!$G$5:$G$5004,$P$11)+ExOn*SUMIFS(مثال_Example!$U$5:$U$804,مثال_Example!$B$5:$B$804,$P$6,مثال_Example!$C$5:$C$804,$P$8,مثال_Example!$D$5:$D$804,$P$7,مثال_Example!$E$5:$E$804,$P$9,مثال_Example!$F$5:$F$804,$B98,مثال_Example!$G$5:$G$804,$P$11))+(SUMIFS(Data!$V$5:$V$5004,Data!$B$5:$B$5004,$P$6,Data!$C$5:$C$5004,$P$8,Data!$D$5:$D$5004,$P$7,Data!$E$5:$E$5004,$P$9,Data!$F$5:$F$5004,$B98,Data!$G$5:$G$5004,$P$11)+ExOn*SUMIFS(مثال_Example!$V$5:$V$804,مثال_Example!$B$5:$B$804,$P$6,مثال_Example!$C$5:$C$804,$P$8,مثال_Example!$D$5:$D$804,$P$7,مثال_Example!$E$5:$E$804,$P$9,مثال_Example!$F$5:$F$804,$B98,مثال_Example!$G$5:$G$804,$P$11)))/$H98) -> — | M98: =IF($C98=0,"لا توجد بيانات",IF(ROUND(IF(ISNUMBER(D98),D98,0),10)<=KeyA_VW,"Very Weak",IF(ROUND(IF(ISNUMBER(D98),D98,0),10)<KeyA_Weak,"Weak",IF(ROUND(IF(ISNUMBER(E98),E98,0),10)<KeyA_Acc,"Acceptable",IF(ROUND(IF(ISNUMBER(E98),E98,0),10)<=KeyA_Good,"Good",IF(ROUND(IF(ISNUMBER(E98),E98,0),10)<KeyA_Out,"Very Good","Outstanding")))))) -> لا توجد بيانات
B101: التحصيل حسب الصف | Attainment by Year (يتجاهل فلتر الصف)
...

Sheet Year_Panel
B1: لوحة الصف | Year Panel
B3: ="اختر الصف والمادة والفترة والمجموعة · العام الدراسي "&Settings!C6&" · الأعداد والنسب والتقديرات حسب البلوك" -> اختر الصف والمادة والفترة والمجموعة · العام الدراسي 2026-27 · الأعداد والنسب والتقديرات حسب البلوك
B4: الدليل | C4: اللوحة | D4: لوحة الصف | E4: المعلمون | F4: إدخال النتائج | G4: هدف التحصيل | H4: هدف التقدم | I4: الإعدادات | J4: المصفوفة | K4: الصفوف | L4: فحوص | M4: اختبارات
P5: معايير الفلاتر (مساعدة)
B6: المادة (Subject) | D6: الصف (Year) | F6: الفترة (Term) | H6: المجموعة (Group) | J6: المعلم (Teacher) | L6: البلوك (Block) | P6: =IF(B7="الكل (All)","*",B7) -> *
B7: الكل (All) | D7: Year 10 | F7: Term 1 | H7: إجمالي الصف (All) | J7: الكل (All) | L7: الكل (All) | P7: =D7 -> Year 10
B8: =IF(Checks!$C$6>0,"⚠ توجد "&Checks!$C$6&" صفوف غير صالحة في Data (راجع عمود الحالة) — لا تدخل في الحساب. ","")&IF(Checks!$C$7>0,"⚠ تنبيهات اتساق: "&Checks!$C$7&" (ورقة Checks). ","")&IF(ExOn=1,"ℹ بيانات «مثال» مُدرجة في التقارير حالياً (Settings).","") | P8: =IF(J7="الكل (All)","*",J7) -> *
P9: =IF(L7="الكل (All)","*",L7) -> *
B10: ="التحصيل | Attainment — "&D7&" · "&F7&" · "&H7 -> التحصيل | Attainment — Year 10 · Term 1 · إجمالي الصف (All) | P10: =F7 -> Term 1
B11: طلاب بنتائج Students with results | D11: At & Above | F11: Above | H11: حكم التحصيل Attainment rating | J11: Δ At & Above مقابل Baseline | L11: Δ Above مقابل Baseline | P11: =H7 -> إجمالي الصف (All)
B12: =$Q$13 -> 0 | D12: =IF($Q$13=0,"لا توجد بيانات",$Q$14/$Q$13) -> لا توجد بيانات | F12: =IF($Q$13=0,"لا توجد بيانات",$Q$15/$Q$13) -> لا توجد بيانات | H12: =IF($Q$13=0,"لا توجد بيانات",IF(ROUND($Q$14/$Q$13,10)<=KeyA_VW,"Very Weak",IF(ROUND($Q$14/$Q$13,10)<KeyA_Weak,"Weak",IF(ROUND($Q$15/$Q$13,10)<KeyA_Acc,"Acceptable",IF(ROUND($Q$15/$Q$13,10)<=KeyA_Good,"Good",IF(ROUND($Q$15/$Q$13,10)<KeyA_Out,"Very Good","Outstanding")))))) -> لا توجد بيانات | J12: =IF(OR($P$10="Baseline",$Q$13=0,$Q$16=0),"—",$Q$14/$Q$13-$Q$17/$Q$16) -> — | L12: =IF(OR($P$10="Baseline",$Q$13=0,$Q$16=0),"—",$Q$15/$Q$13-$Q$18/$Q$16) -> — | P12: قيم مساعدة (للقراءة فقط)
B13: =IF($Q$13=0,"لا توجد بيانات","غياب/بدون نتيجة مستبعد") -> لا توجد بيانات | D13: =IF($Q$13=0,"",$Q$14&" من "&$Q$13&" طالب") | F13: =IF($Q$13=0,"",$Q$15&" من "&$Q$13&" طالب") | H13: حسب المفتاح في Settings | J13: نقاط مئوية (الفترة المختارة − Baseline) | L13: نقاط مئوية (الفترة المختارة − Baseline) | P13: طلاب بنتائج | Q13: =(SUMIFS(Data!$Q$5:$Q$5004,Data!$B$5:$B$5004,$P$6,Data!$D$5:$D$5004,$P$7,Data!$C$5:$C$5004,$P$8,Data!$E$5:$E$5004,$P$9,Data!$F$5:$F$5004,$P$10,Data!$G$5:$G$5004,$P$11)+ExOn*SUMIFS(مثال_Example!$Q$5:$Q$804,مثال_Example!$B$5:$B$804,$P$6,مثال_Example!$D$5:$D$804,$P$7,مثال_Example!$C$5:$C$804,$P$8,مثال_Example!$E$5:$E$804,$P$9,مثال_Example!$F$5:$F$804,$P$10,مثال_Example!$G$5:$G$804,$P$11)) -> 0
P14: At & Above | Q14: =(SUMIFS(Data!$R$5:$R$5004,Data!$B$5:$B$5004,$P$6,Data!$D$5:$D$5004,$P$7,Data!$C$5:$C$5004,$P$8,Data!$E$5:$E$5004,$P$9,Data!$F$5:$F$5004,$P$10,Data!$G$5:$G$5004,$P$11)+ExOn*SUMIFS(مثال_Example!$R$5:$R$804,مثال_Example!$B$5:$B$804,$P$6,مثال_Example!$D$5:$D$804,$P$7,مثال_Example!$C$5:$C$804,$P$8,مثال_Example!$E$5:$E$804,$P$9,مثال_Example!$F$5:$F$804,$P$10,مثال_Example!$G$5:$G$804,$P$11)) -> 0
B15: التقدم | Progress | P15: Above | Q15: =(SUMIFS(Data!$S$5:$S$5004,Data!$B$5:$B$5004,$P$6,Data!$D$5:$D$5004,$P$7,Data!$C$5:$C$5004,$P$8,Data!$E$5:$E$5004,$P$9,Data!$F$5:$F$5004,$P$10,Data!$G$5:$G$5004,$P$11)+ExOn*SUMIFS(مثال_Example!$S$5:$S$804,مثال_Example!$B$5:$B$804,$P$6,مثال_Example!$D$5:$D$804,$P$7,مثال_Example!$C$5:$C$804,$P$8,مثال_Example!$E$5:$E$804,$P$9,مثال_Example!$F$5:$F$804,$P$10,مثال_Example!$G$5:$G$804,$P$11)) -> 0
B16: حالات تقدم قابلة للتصنيف Progress cases | D16: Less Than Expected | F16: Expected | H16: Better Than Expected | J16: Expected & Better | L16: حكم التقدم Progress rating | P16: Baseline: بنتائج | Q16: =(SUMIFS(Data!$Q$5:$Q$5004,Data!$B$5:$B$5004,$P$6,Data!$D$5:$D$5004,$P$7,Data!$C$5:$C$5004,$P$8,Data!$E$5:$E$5004,$P$9,Data!$F$5:$F$5004,"Baseline",Data!$G$5:$G$5004,$P$11)+ExOn*SUMIFS(مثال_Example!$Q$5:$Q$804,مثال_Example!$B$5:$B$804,$P$6,مثال_Example!$D$5:$D$804,$P$7,مثال_Example!$C$5:$C$804,$P$8,مثال_Example!$E$5:$E$804,$P$9,مثال_Example!$F$5:$F$804,"Baseline",مثال_Example!$G$5:$G$804,$P$11)) -> 0
B17: =$Q$24 -> 0 | D17: =IF($Q$24=0,"لا توجد بيانات",$Q$19/$Q$24) -> لا توجد بيانات | F17: =IF($Q$24=0,"لا توجد بيانات",$Q$20/$Q$24) -> لا توجد بيانات | H17: =IF($Q$24=0,"لا توجد بيانات",$Q$21/$Q$24) -> لا توجد بيانات | J17: =IF($Q$24=0,"لا توجد بيانات",($Q$20+$Q$21)/$Q$24) -> لا توجد بيانات | L17: =IF($Q$24=0,"لا توجد بيانات",IF(ROUND(($Q$20+$Q$21)/$Q$24,10)<=KeyP_VW,"Very Weak",IF(ROUND(($Q$20+$Q$21)/$Q$24,10)<KeyP_Weak,"Weak",IF(ROUND($Q$21/$Q$24,10)<KeyP_Acc,"Acceptable",IF(ROUND($Q$21/$Q$24,10)<=KeyP_Good,"Good",IF(ROUND($Q$21/$Q$24,10)<KeyP_Out,"Very Good","Outstanding")))))) -> لا توجد بيانات | P17: Baseline: At | Q17: =(SUMIFS(Data!$R$5:$R$5004,Data!$B$5:$B$5004,$P$6,Data!$D$5:$D$5004,$P$7,Data!$C$5:$C$5004,$P$8,Data!$E$5:$E$5004,$P$9,Data!$F$5:$F$5004,"Baseline",Data!$G$5:$G$5004,$P$11)+ExOn*SUMIFS(مثال_Example!$R$5:$R$804,مثال_Example!$B$5:$B$804,$P$6,مثال_Example!$D$5:$D$804,$P$7,مثال_Example!$C$5:$C$804,$P$8,مثال_Example!$E$5:$E$804,$P$9,مثال_Example!$F$5:$F$804,"Baseline",مثال_Example!$G$5:$G$804,$P$11)) -> 0
B18: ="مستبعد: U "&$Q$22&" · بدون Start "&$Q$23 -> مستبعد: U 0 · بدون Start 0 | D18: =IF($Q$24=0,"",$Q$19&" طالب") | F18: =IF($Q$24=0,"",$Q$20&" طالب") | H18: =IF($Q$24=0,"",$Q$21&" طالب") | J18: =IF($Q$24=0,"",($Q$20+$Q$21)&" طالب") | L18: حسب مفتاح التقدم في Settings | P18: Baseline: Above | Q18: =(SUMIFS(Data!$S$5:$S$5004,Data!$B$5:$B$5004,$P$6,Data!$D$5:$D$5004,$P$7,Data!$C$5:$C$5004,$P$8,Data!$E$5:$E$5004,$P$9,Data!$F$5:$F$5004,"Baseline",Data!$G$5:$G$5004,$P$11)+ExOn*SUMIFS(مثال_Example!$S$5:$S$804,مثال_Example!$B$5:$B$804,$P$6,مثال_Example!$D$5:$D$804,$P$7,مثال_Example!$C$5:$C$804,$P$8,مثال_Example!$E$5:$E$804,$P$9,مثال_Example!$F$5:$F$804,"Baseline",مثال_Example!$G$5:$G$804,$P$11)) -> 0
P19: Less | Q19: =(SUMIFS(Data!$T$5:$T$5004,Data!$B$5:$B$5004,$P$6,Data!$D$5:$D$5004,$P$7,Data!$C$5:$C$5004,$P$8,Data!$E$5:$E$5004,$P$9,Data!$F$5:$F$5004,$P$10,Data!$G$5:$G$5004,$P$11)+ExOn*SUMIFS(مثال_Example!$T$5:$T$804,مثال_Example!$B$5:$B$804,$P$6,مثال_Example!$D$5:$D$804,$P$7,مثال_Example!$C$5:$C$804,$P$8,مثال_Example!$E$5:$E$804,$P$9,مثال_Example!$F$5:$F$804,$P$10,مثال_Example!$G$5:$G$804,$P$11)) -> 0
B20: الرسوم | Charts | P20: Expected | Q20: =(SUMIFS(Data!$U$5:$U$5004,Data!$B$5:$B$5004,$P$6,Data!$D$5:$D$5004,$P$7,Data!$C$5:$C$5004,$P$8,Data!$E$5:$E$5004,$P$9,Data!$F$5:$F$5004,$P$10,Data!$G$5:$G$5004,$P$11)+ExOn*SUMIFS(مثال_Example!$U$5:$U$804,مثال_Example!$B$5:$B$804,$P$6,مثال_Example!$D$5:$D$804,$P$7,مثال_Example!$C$5:$C$804,$P$8,مثال_Example!$E$5:$E$804,$P$9,مثال_Example!$F$5:$F$804,$P$10,مثال_Example!$G$5:$G$804,$P$11)) -> 0
P21: Better | Q21: =(SUMIFS(Data!$V$5:$V$5004,Data!$B$5:$B$5004,$P$6,Data!$D$5:$D$5004,$P$7,Data!$C$5:$C$5004,$P$8,Data!$E$5:$E$5004,$P$9,Data!$F$5:$F$5004,$P$10,Data!$G$5:$G$5004,$P$11)+ExOn*SUMIFS(مثال_Example!$V$5:$V$804,مثال_Example!$B$5:$B$804,$P$6,مثال_Example!$D$5:$D$804,$P$7,مثال_Example!$C$5:$C$804,$P$8,مثال_Example!$E$5:$E$804,$P$9,مثال_Example!$F$5:$F$804,$P$10,مثال_Example!$G$5:$G$804,$P$11)) -> 0
P22: U مستبعد | Q22: =(SUMIFS(Data!$W$5:$W$5004,Data!$B$5:$B$5004,$P$6,Data!$D$5:$D$5004,$P$7,Data!$C$5:$C$5004,$P$8,Data!$E$5:$E$5004,$P$9,Data!$F$5:$F$5004,$P$10,Data!$G$5:$G$5004,$P$11)+ExOn*SUMIFS(مثال_Example!$W$5:$W$804,مثال_Example!$B$5:$B$804,$P$6,مثال_Example!$D$5:$D$804,$P$7,مثال_Example!$C$5:$C$804,$P$8,مثال_Example!$E$5:$E$804,$P$9,مثال_Example!$F$5:$F$804,$P$10,مثال_Example!$G$5:$G$804,$P$11)) -> 0
P23: بدون Start | Q23: =(SUMIFS(Data!$X$5:$X$5004,Data!$B$5:$B$5004,$P$6,Data!$D$5:$D$5004,$P$7,Data!$C$5:$C$5004,$P$8,Data!$E$5:$E$5004,$P$9,Data!$F$5:$F$5004,$P$10,Data!$G$5:$G$5004,$P$11)+ExOn*SUMIFS(مثال_Example!$X$5:$X$804,مثال_Example!$B$5:$B$804,$P$6,مثال_Example!$D$5:$D$804,$P$7,مثال_Example!$C$5:$C$804,$P$8,مثال_Example!$E$5:$E$804,$P$9,مثال_Example!$F$5:$F$804,$P$10,مثال_Example!$G$5:$G$804,$P$11)) -> 0
P24: حالات التقدم | Q24: =$Q$19+$Q$20+$Q$21 -> 0
H70: مفتاح الأحكام | Rating key
H71: Outstanding | J71: At & Above ≥ 75% و Above ≥ 75%
H72: Very Good | J72: At & Above ≥ 75% و Above > 60% و < 75%
H73: Good | J73: At & Above ≥ 75% و Above من 50% إلى 60%
H74: Acceptable | J74: At & Above ≥ 75% و Above < 50%
H75: Weak | J75: At & Above بين 15% و 75% (أقل من 75%)
H76: Very Weak | J76: At & Above ≤ 15%
H77: Less Than Expected | J77: التصنيف يُؤخذ من مصفوفة التقدم (Progress_Matrix) بالبحث عن Start Point والدرجة الحالية. U وحالات بلا Start تُستبعد من التقدم وتُعرض أعدادها.
H78: Expected
H79: Better Than Expected
B93: المقارنة مع نقطة البداية حسب الفترة (لهذا الصف) | By Term
B94: الفترة Term | C94: طلاب بنتائج | D94: At & Above % | E94: Above % | F94: Δ At&Above مقابل BSL | G94: Δ Above مقابل BSL | H94: حالات تقدم | I94: Less % | J94: Expected % | K94: Better % | L94: Expected&Better % | M94: حكم التحصيل
B95: Baseline | C95: =(SUMIFS(Data!$Q$5:$Q$5004,Data!$B$5:$B$5004,$P$6,Data!$D$5:$D$5004,$P$7,Data!$C$5:$C$5004,$P$8,Data!$E$5:$E$5004,$P$9,Data!$F$5:$F$5004,$B95,Data!$G$5:$G$5004,$P$11)+ExOn*SUMIFS(مثال_Example!$Q$5:$Q$804,مثال_Example!$B$5:$B$804,$P$6,مثال_Example!$D$5:$D$804,$P$7,مثال_Example!$C$5:$C$804,$P$8,مثال_Example!$E$5:$E$804,$P$9,مثال_Example!$F$5:$F$804,$B95,مثال_Example!$G$5:$G$804,$P$11)) -> 0 | D95: =IF($C95=0,"—",(SUMIFS(Data!$R$5:$R$5004,Data!$B$5:$B$5004,$P$6,Data!$D$5:$D$5004,$P$7,Data!$C$5:$C$5004,$P$8,Data!$E$5:$E$5004,$P$9,Data!$F$5:$F$5004,$B95,Data!$G$5:$G$5004,$P$11)+ExOn*SUMIFS(مثال_Example!$R$5:$R$804,مثال_Example!$B$5:$B$804,$P$6,مثال_Example!$D$5:$D$804,$P$7,مثال_Example!$C$5:$C$804,$P$8,مثال_Example!$E$5:$E$804,$P$9,مثال_Example!$F$5:$F$804,$B95,مثال_Example!$G$5:$G$804,$P$11))/$C95) -> — | E95: =IF($C95=0,"—",(SUMIFS(Data!$S$5:$S$5004,Data!$B$5:$B$5004,$P$6,Data!$D$5:$D$5004,$P$7,Data!$C$5:$C$5004,$P$8,Data!$E$5:$E$5004,$P$9,Data!$F$5:$F$5004,$B95,Data!$G$5:$G$5004,$P$11)+ExOn*SUMIFS(مثال_Example!$S$5:$S$804,مثال_Example!$B$5:$B$804,$P$6,مثال_Example!$D$5:$D$804,$P$7,مثال_Example!$C$5:$C$804,$P$8,مثال_Example!$E$5:$E$804,$P$9,مثال_Example!$F$5:$F$804,$B95,مثال_Example!$G$5:$G$804,$P$11))/$C95) -> — | F95: =IF(OR($B95="Baseline",NOT(ISNUMBER(D95)),NOT(ISNUMBER(D$95))),"—",D95-D$95) -> — | G95: =IF(OR($B95="Baseline",NOT(ISNUMBER(E95)),NOT(ISNUMBER(E$95))),"—",E95-E$95) -> — | H95: =(SUMIFS(Data!$T$5:$T$5004,Data!$B$5:$B$5004,$P$6,Data!$D$5:$D$5004,$P$7,Data!$C$5:$C$5004,$P$8,Data!$E$5:$E$5004,$P$9,Data!$F$5:$F$5004,$B95,Data!$G$5:$G$5004,$P$11)+ExOn*SUMIFS(مثال_Example!$T$5:$T$804,مثال_Example!$B$5:$B$804,$P$6,مثال_Example!$D$5:$D$804,$P$7,مثال_Example!$C$5:$C$804,$P$8,مثال_Example!$E$5:$E$804,$P$9,مثال_Example!$F$5:$F$804,$B95,مثال_Example!$G$5:$G$804,$P$11))+(SUMIFS(Data!$U$5:$U$5004,Data!$B$5:$B$5004,$P$6,Data!$D$5:$D$5004,$P$7,Data!$C$5:$C$5004,$P$8,Data!$E$5:$E$5004,$P$9,Data!$F$5:$F$5004,$B95,Data!$G$5:$G$5004,$P$11)+ExOn*SUMIFS(مثال_Example!$U$5:$U$804,مثال_Example!$B$5:$B$804,$P$6,مثال_Example!$D$5:$D$804,$P$7,مثال_Example!$C$5:$C$804,$P$8,مثال_Example!$E$5:$E$804,$P$9,مثال_Example!$F$5:$F$804,$B95,مثال_Example!$G$5:$G$804,$P$11))+(SUMIFS(Data!$V$5:$V$5004,Data!$B$5:$B$5004,$P$6,Data!$D$5:$D$5004,$P$7,Data!$C$5:$C$5004,$P$8,Data!$E$5:$E$5004,$P$9,Data!$F$5:$F$5004,$B95,Data!$G$5:$G$5004,$P$11)+ExOn*SUMIFS(مثال_Example!$V$5:$V$804,مثال_Example!$B$5:$B$804,$P$6,مثال_Example!$D$5:$D$804,$P$7,مثال_Example!$C$5:$C$804,$P$8,مثال_Example!$E$5:$E$804,$P$9,مثال_Example!$F$5:$F$804,$B95,مثال_Example!$G$5:$G$804,$P$11)) -> 0 | I95: =IF($H95=0,"—",(SUMIFS(Data!$T$5:$T$5004,Data!$B$5:$B$5004,$P$6,Data!$D$5:$D$5004,$P$7,Data!$C$5:$C$5004,$P$8,Data!$E$5:$E$5004,$P$9,Data!$F$5:$F$5004,$B95,Data!$G$5:$G$5004,$P$11)+ExOn*SUMIFS(مثال_Example!$T$5:$T$804,مثال_Example!$B$5:$B$804,$P$6,مثال_Example!$D$5:$D$804,$P$7,مثال_Example!$C$5:$C$804,$P$8,مثال_Example!$E$5:$E$804,$P$9,مثال_Example!$F$5:$F$804,$B95,مثال_Example!$G$5:$G$804,$P$11))/$H95) -> — | J95: =IF($H95=0,"—",(SUMIFS(Data!$U$5:$U$5004,Data!$B$5:$B$5004,$P$6,Data!$D$5:$D$5004,$P$7,Data!$C$5:$C$5004,$P$8,Data!$E$5:$E$5004,$P$9,Data!$F$5:$F$5004,$B95,Data!$G$5:$G$5004,$P$11)+ExOn*SUMIFS(مثال_Example!$U$5:$U$804,مثال_Example!$B$5:$B$804,$P$6,مثال_Example!$D$5:$D$804,$P$7,مثال_Example!$C$5:$C$804,$P$8,مثال_Example!$E$5:$E$804,$P$9,مثال_Example!$F$5:$F$804,$B95,مثال_Example!$G$5:$G$804,$P$11))/$H95) -> — | K95: =IF($H95=0,"—",(SUMIFS(Data!$V$5:$V$5004,Data!$B$5:$B$5004,$P$6,Data!$D$5:$D$5004,$P$7,Data!$C$5:$C$5004,$P$8,Data!$E$5:$E$5004,$P$9,Data!$F$5:$F$5004,$B95,Data!$G$5:$G$5004,$P$11)+ExOn*SUMIFS(مثال_Example!$V$5:$V$804,مثال_Example!$B$5:$B$804,$P$6,مثال_Example!$D$5:$D$804,$P$7,مثال_Example!$C$5:$C$804,$P$8,مثال_Example!$E$5:$E$804,$P$9,مثال_Example!$F$5:$F$804,$B95,مثال_Example!$G$5:$G$804,$P$11))/$H95) -> — | L95: =IF($H95=0,"—",((SUMIFS(Data!$U$5:$U$5004,Data!$B$5:$B$5004,$P$6,Data!$D$5:$D$5004,$P$7,Data!$C$5:$C$5004,$P$8,Data!$E$5:$E$5004,$P$9,Data!$F$5:$F$5004,$B95,Data!$G$5:$G$5004,$P$11)+ExOn*SUMIFS(مثال_Example!$U$5:$U$804,مثال_Example!$B$5:$B$804,$P$6,مثال_Example!$D$5:$D$804,$P$7,مثال_Example!$C$5:$C$804,$P$8,مثال_Example!$E$5:$E$804,$P$9,مثال_Example!$F$5:$F$804,$B95,مثال_Example!$G$5:$G$804,$P$11))+(SUMIFS(Data!$V$5:$V$5004,Data!$B$5:$B$5004,$P$6,Data!$D$5:$D$5004,$P$7,Data!$C$5:$C$5004,$P$8,Data!$E$5:$E$5004,$P$9,Data!$F$5:$F$5004,$B95,Data!$G$5:$G$5004,$P$11)+ExOn*SUMIFS(مثال_Example!$V$5:$V$804,مثال_Example!$B$5:$B$804,$P$6,مثال_Example!$D$5:$D$804,$P$7,مثال_Example!$C$5:$C$804,$P$8,مثال_Example!$E$5:$E$804,$P$9,مثال_Example!$F$5:$F$804,$B95,مثال_Example!$G$5:$G$804,$P$11)))/$H95) -> — | M95: =IF($C95=0,"لا توجد بيانات",IF(ROUND(IF(ISNUMBER(D95),D95,0),10)<=KeyA_VW,"Very Weak",IF(ROUND(IF(ISNUMBER(D95),D95,0),10)<KeyA_Weak,"Weak",IF(ROUND(IF(ISNUMBER(E95),E95,0),10)<KeyA_Acc,"Acceptable",IF(ROUND(IF(ISNUMBER(E95),E95,0),10)<=KeyA_Good,"Good",IF(ROUND(IF(ISNUMBER(E95),E95,0),10)<KeyA_Out,"Very Good","Outstanding")))))) -> لا توجد بيانات
B96: Term 1 | C96: =(SUMIFS(Data!$Q$5:$Q$5004,Data!$B$5:$B$5004,$P$6,Data!$D$5:$D$5004,$P$7,Data!$C$5:$C$5004,$P$8,Data!$E$5:$E$5004,$P$9,Data!$F$5:$F$5004,$B96,Data!$G$5:$G$5004,$P$11)+ExOn*SUMIFS(مثال_Example!$Q$5:$Q$804,مثال_Example!$B$5:$B$804,$P$6,مثال_Example!$D$5:$D$804,$P$7,مثال_Example!$C$5:$C$804,$P$8,مثال_Example!$E$5:$E$804,$P$9,مثال_Example!$F$5:$F$804,$B96,مثال_Example!$G$5:$G$804,$P$11)) -> 0 | D96: =IF($C96=0,"—",(SUMIFS(Data!$R$5:$R$5004,Data!$B$5:$B$5004,$P$6,Data!$D$5:$D$5004,$P$7,Data!$C$5:$C$5004,$P$8,Data!$E$5:$E$5004,$P$9,Data!$F$5:$F$5004,$B96,Data!$G$5:$G$5004,$P$11)+ExOn*SUMIFS(مثال_Example!$R$5:$R$804,مثال_Example!$B$5:$B$804,$P$6,مثال_Example!$D$5:$D$804,$P$7,مثال_Example!$C$5:$C$804,$P$8,مثال_Example!$E$5:$E$804,$P$9,مثال_Example!$F$5:$F$804,$B96,مثال_Example!$G$5:$G$804,$P$11))/$C96) -> — | E96: =IF($C96=0,"—",(SUMIFS(Data!$S$5:$S$5004,Data!$B$5:$B$5004,$P$6,Data!$D$5:$D$5004,$P$7,Data!$C$5:$C$5004,$P$8,Data!$E$5:$E$5004,$P$9,Data!$F$5:$F$5004,$B96,Data!$G$5:$G$5004,$P$11)+ExOn*SUMIFS(مثال_Example!$S$5:$S$804,مثال_Example!$B$5:$B$804,$P$6,مثال_Example!$D$5:$D$804,$P$7,مثال_Example!$C$5:$C$804,$P$8,مثال_Example!$E$5:$E$804,$P$9,مثال_Example!$F$5:$F$804,$B96,مثال_Example!$G$5:$G$804,$P$11))/$C96) -> — | F96: =IF(OR($B96="Baseline",NOT(ISNUMBER(D96)),NOT(ISNUMBER(D$95))),"—",D96-D$95) -> — | G96: =IF(OR($B96="Baseline",NOT(ISNUMBER(E96)),NOT(ISNUMBER(E$95))),"—",E96-E$95) -> — | H96: =(SUMIFS(Data!$T$5:$T$5004,Data!$B$5:$B$5004,$P$6,Data!$D$5:$D$5004,$P$7,Data!$C$5:$C$5004,$P$8,Data!$E$5:$E$5004,$P$9,Data!$F$5:$F$5004,$B96,Data!$G$5:$G$5004,$P$11)+ExOn*SUMIFS(مثال_Example!$T$5:$T$804,مثال_Example!$B$5:$B$804,$P$6,مثال_Example!$D$5:$D$804,$P$7,مثال_Example!$C$5:$C$804,$P$8,مثال_Example!$E$5:$E$804,$P$9,مثال_Example!$F$5:$F$804,$B96,مثال_Example!$G$5:$G$804,$P$11))+(SUMIFS(Data!$U$5:$U$5004,Data!$B$5:$B$5004,$P$6,Data!$D$5:$D$5004,$P$7,Data!$C$5:$C$5004,$P$8,Data!$E$5:$E$5004,$P$9,Data!$F$5:$F$5004,$B96,Data!$G$5:$G$5004,$P$11)+ExOn*SUMIFS(مثال_Example!$U$5:$U$804,مثال_Example!$B$5:$B$804,$P$6,مثال_Example!$D$5:$D$804,$P$7,مثال_Example!$C$5:$C$804,$P$8,مثال_Example!$E$5:$E$804,$P$9,مثال_Example!$F$5:$F$804,$B96,مثال_Example!$G$5:$G$804,$P$11))+(SUMIFS(Data!$V$5:$V$5004,Data!$B$5:$B$5004,$P$6,Data!$D$5:$D$5004,$P$7,Data!$C$5:$C$5004,$P$8,Data!$E$5:$E$5004,$P$9,Data!$F$5:$F$5004,$B96,Data!$G$5:$G$5004,$P$11)+ExOn*SUMIFS(مثال_Example!$V$5:$V$804,مثال_Example!$B$5:$B$804,$P$6,مثال_Example!$D$5:$D$804,$P$7,مثال_Example!$C$5:$C$804,$P$8,مثال_Example!$E$5:$E$804,$P$9,مثال_Example!$F$5:$F$804,$B96,مثال_Example!$G$5:$G$804,$P$11)) -> 0 | I96: =IF($H96=0,"—",(SUMIFS(Data!$T$5:$T$5004,Data!$B$5:$B$5004,$P$6,Data!$D$5:$D$5004,$P$7,Data!$C$5:$C$5004,$P$8,Data!$E$5:$E$5004,$P$9,Data!$F$5:$F$5004,$B96,Data!$G$5:$G$5004,$P$11)+ExOn*SUMIFS(مثال_Example!$T$5:$T$804,مثال_Example!$B$5:$B$804,$P$6,مثال_Example!$D$5:$D$804,$P$7,مثال_Example!$C$5:$C$804,$P$8,مثال_Example!$E$5:$E$804,$P$9,مثال_Example!$F$5:$F$804,$B96,مثال_Example!$G$5:$G$804,$P$11))/$H96) -> — | J96: =IF($H96=0,"—",(SUMIFS(Data!$U$5:$U$5004,Data!$B$5:$B$5004,$P$6,Data!$D$5:$D$5004,$P$7,Data!$C$5:$C$5004,$P$8,Data!$E$5:$E$5004,$P$9,Data!$F$5:$F$5004,$B96,Data!$G$5:$G$5004,$P$11)+ExOn*SUMIFS(مثال_Example!$U$5:$U$804,مثال_Example!$B$5:$B$804,$P$6,مثال_Example!$D$5:$D$804,$P$7,مثال_Example!$C$5:$C$804,$P$8,مثال_Example!$E$5:$E$804,$P$9,مثال_Example!$F$5:$F$804,$B96,مثال_Example!$G$5:$G$804,$P$11))/$H96) -> — | K96: =IF($H96=0,"—",(SUMIFS(Data!$V$5:$V$5004,Data!$B$5:$B$5004,$P$6,Data!$D$5:$D$5004,$P$7,Data!$C$5:$C$5004,$P$8,Data!$E$5:$E$5004,$P$9,Data!$F$5:$F$5004,$B96,Data!$G$5:$G$5004,$P$11)+ExOn*SUMIFS(مثال_Example!$V$5:$V$804,مثال_Example!$B$5:$B$804,$P$6,مثال_Example!$D$5:$D$804,$P$7,مثال_Example!$C$5:$C$804,$P$8,مثال_Example!$E$5:$E$804,$P$9,مثال_Example!$F$5:$F$804,$B96,مثال_Example!$G$5:$G$804,$P$11))/$H96) -> — | L96: =IF($H96=0,"—",((SUMIFS(Data!$U$5:$U$5004,Data!$B$5:$B$5004,$P$6,Data!$D$5:$D$5004,$P$7,Data!$C$5:$C$5004,$P$8,Data!$E$5:$E$5004,$P$9,Data!$F$5:$F$5004,$B96,Data!$G$5:$G$5004,$P$11)+ExOn*SUMIFS(مثال_Example!$U$5:$U$804,مثال_Example!$B$5:$B$804,$P$6,مثال_Example!$D$5:$D$804,$P$7,مثال_Example!$C$5:$C$804,$P$8,مثال_Example!$E$5:$E$804,$P$9,مثال_Example!$F$5:$F$804,$B96,مثال_Example!$G$5:$G$804,$P$11))+(SUMIFS(Data!$V$5:$V$5004,Data!$B$5:$B$5004,$P$6,Data!$D$5:$D$5004,$P$7,Data!$C$5:$C$5004,$P$8,Data!$E$5:$E$5004,$P$9,Data!$F$5:$F$5004,$B96,Data!$G$5:$G$5004,$P$11)+ExOn*SUMIFS(مثال_Example!$V$5:$V$804,مثال_Example!$B$5:$B$804,$P$6,مثال_Example!$D$5:$D$804,$P$7,مثال_Example!$C$5:$C$804,$P$8,مثال_Example!$E$5:$E$804,$P$9,مثال_Example!$F$5:$F$804,$B96,مثال_Example!$G$5:$G$804,$P$11)))/$H96) -> — | M96: =IF($C96=0,"لا توجد بيانات",IF(ROUND(IF(ISNUMBER(D96),D96,0),10)<=KeyA_VW,"Very Weak",IF(ROUND(IF(ISNUMBER(D96),D96,0),10)<KeyA_Weak,"Weak",IF(ROUND(IF(ISNUMBER(E96),E96,0),10)<KeyA_Acc,"Acceptable",IF(ROUND(IF(ISNUMBER(E96),E96,0),10)<=KeyA_Good,"Good",IF(ROUND(IF(ISNUMBER(E96),E96,0),10)<KeyA_Out,"Very Good","Outstanding")))))) -> لا توجد بيانات
B97: Term 2 | C97: =(SUMIFS(Data!$Q$5:$Q$5004,Data!$B$5:$B$5004,$P$6,Data!$D$5:$D$5004,$P$7,Data!$C$5:$C$5004,$P$8,Data!$E$5:$E$5004,$P$9,Data!$F$5:$F$5004,$B97,Data!$G$5:$G$5004,$P$11)+ExOn*SUMIFS(مثال_Example!$Q$5:$Q$804,مثال_Example!$B$5:$B$804,$P$6,مثال_Example!$D$5:$D$804,$P$7,مثال_Example!$C$5:$C$804,$P$8,مثال_Example!$E$5:$E$804,$P$9,مثال_Example!$F$5:$F$804,$B97,مثال_Example!$G$5:$G$804,$P$11)) -> 0 | D97: =IF($C97=0,"—",(SUMIFS(Data!$R$5:$R$5004,Data!$B$5:$B$5004,$P$6,Data!$D$5:$D$5004,$P$7,Data!$C$5:$C$5004,$P$8,Data!$E$5:$E$5004,$P$9,Data!$F$5:$F$5004,$B97,Data!$G$5:$G$5004,$P$11)+ExOn*SUMIFS(مثال_Example!$R$5:$R$804,مثال_Example!$B$5:$B$804,$P$6,مثال_Example!$D$5:$D$804,$P$7,مثال_Example!$C$5:$C$804,$P$8,مثال_Example!$E$5:$E$804,$P$9,مثال_Example!$F$5:$F$804,$B97,مثال_Example!$G$5:$G$804,$P$11))/$C97) -> — | E97: =IF($C97=0,"—",(SUMIFS(Data!$S$5:$S$5004,Data!$B$5:$B$5004,$P$6,Data!$D$5:$D$5004,$P$7,Data!$C$5:$C$5004,$P$8,Data!$E$5:$E$5004,$P$9,Data!$F$5:$F$5004,$B97,Data!$G$5:$G$5004,$P$11)+ExOn*SUMIFS(مثال_Example!$S$5:$S$804,مثال_Example!$B$5:$B$804,$P$6,مثال_Example!$D$5:$D$804,$P$7,مثال_Example!$C$5:$C$804,$P$8,مثال_Example!$E$5:$E$804,$P$9,مثال_Example!$F$5:$F$804,$B97,مثال_Example!$G$5:$G$804,$P$11))/$C97) -> — | F97: =IF(OR($B97="Baseline",NOT(ISNUMBER(D97)),NOT(ISNUMBER(D$95))),"—",D97-D$95) -> — | G97: =IF(OR($B97="Baseline",NOT(ISNUMBER(E97)),NOT(ISNUMBER(E$95))),"—",E97-E$95) -> — | H97: =(SUMIFS(Data!$T$5:$T$5004,Data!$B$5:$B$5004,$P$6,Data!$D$5:$D$5004,$P$7,Data!$C$5:$C$5004,$P$8,Data!$E$5:$E$5004,$P$9,Data!$F$5:$F$5004,$B97,Data!$G$5:$G$5004,$P$11)+ExOn*SUMIFS(مثال_Example!$T$5:$T$804,مثال_Example!$B$5:$B$804,$P$6,مثال_Example!$D$5:$D$804,$P$7,مثال_Example!$C$5:$C$804,$P$8,مثال_Example!$E$5:$E$804,$P$9,مثال_Example!$F$5:$F$804,$B97,مثال_Example!$G$5:$G$804,$P$11))+(SUMIFS(Data!$U$5:$U$5004,Data!$B$5:$B$5004,$P$6,Data!$D$5:$D$5004,$P$7,Data!$C$5:$C$5004,$P$8,Data!$E$5:$E$5004,$P$9,Data!$F$5:$F$5004,$B97,Data!$G$5:$G$5004,$P$11)+ExOn*SUMIFS(مثال_Example!$U$5:$U$804,مثال_Example!$B$5:$B$804,$P$6,مثال_Example!$D$5:$D$804,$P$7,مثال_Example!$C$5:$C$804,$P$8,مثال_Example!$E$5:$E$804,$P$9,مثال_Example!$F$5:$F$804,$B97,مثال_Example!$G$5:$G$804,$P$11))+(SUMIFS(Data!$V$5:$V$5004,Data!$B$5:$B$5004,$P$6,Data!$D$5:$D$5004,$P$7,Data!$C$5:$C$5004,$P$8,Data!$E$5:$E$5004,$P$9,Data!$F$5:$F$5004,$B97,Data!$G$5:$G$5004,$P$11)+ExOn*SUMIFS(مثال_Example!$V$5:$V$804,مثال_Example!$B$5:$B$804,$P$6,مثال_Example!$D$5:$D$804,$P$7,مثال_Example!$C$5:$C$804,$P$8,مثال_Example!$E$5:$E$804,$P$9,مثال_Example!$F$5:$F$804,$B97,مثال_Example!$G$5:$G$804,$P$11)) -> 0 | I97: =IF($H97=0,"—",(SUMIFS(Data!$T$5:$T$5004,Data!$B$5:$B$5004,$P$6,Data!$D$5:$D$5004,$P$7,Data!$C$5:$C$5004,$P$8,Data!$E$5:$E$5004,$P$9,Data!$F$5:$F$5004,$B97,Data!$G$5:$G$5004,$P$11)+ExOn*SUMIFS(مثال_Example!$T$5:$T$804,مثال_Example!$B$5:$B$804,$P$6,مثال_Example!$D$5:$D$804,$P$7,مثال_Example!$C$5:$C$804,$P$8,مثال_Example!$E$5:$E$804,$P$9,مثال_Example!$F$5:$F$804,$B97,مثال_Example!$G$5:$G$804,$P$11))/$H97) -> — | J97: =IF($H97=0,"—",(SUMIFS(Data!$U$5:$U$5004,Data!$B$5:$B$5004,$P$6,Data!$D$5:$D$5004,$P$7,Data!$C$5:$C$5004,$P$8,Data!$E$5:$E$5004,$P$9,Data!$F$5:$F$5004,$B97,Data!$G$5:$G$5004,$P$11)+ExOn*SUMIFS(مثال_Example!$U$5:$U$804,مثال_Example!$B$5:$B$804,$P$6,مثال_Example!$D$5:$D$804,$P$7,مثال_Example!$C$5:$C$804,$P$8,مثال_Example!$E$5:$E$804,$P$9,مثال_Example!$F$5:$F$804,$B97,مثال_Example!$G$5:$G$804,$P$11))/$H97) -> — | K97: =IF($H97=0,"—",(SUMIFS(Data!$V$5:$V$5004,Data!$B$5:$B$5004,$P$6,Data!$D$5:$D$5004,$P$7,Data!$C$5:$C$5004,$P$8,Data!$E$5:$E$5004,$P$9,Data!$F$5:$F$5004,$B97,Data!$G$5:$G$5004,$P$11)+ExOn*SUMIFS(مثال_Example!$V$5:$V$804,مثال_Example!$B$5:$B$804,$P$6,مثال_Example!$D$5:$D$804,$P$7,مثال_Example!$C$5:$C$804,$P$8,مثال_Example!$E$5:$E$804,$P$9,مثال_Example!$F$5:$F$804,$B97,مثال_Example!$G$5:$G$804,$P$11))/$H97) -> — | L97: =IF($H97=0,"—",((SUMIFS(Data!$U$5:$U$5004,Data!$B$5:$B$5004,$P$6,Data!$D$5:$D$5004,$P$7,Data!$C$5:$C$5004,$P$8,Data!$E$5:$E$5004,$P$9,Data!$F$5:$F$5004,$B97,Data!$G$5:$G$5004,$P$11)+ExOn*SUMIFS(مثال_Example!$U$5:$U$804,مثال_Example!$B$5:$B$804,$P$6,مثال_Example!$D$5:$D$804,$P$7,مثال_Example!$C$5:$C$804,$P$8,مثال_Example!$E$5:$E$804,$P$9,مثال_Example!$F$5:$F$804,$B97,مثال_Example!$G$5:$G$804,$P$11))+(SUMIFS(Data!$V$5:$V$5004,Data!$B$5:$B$5004,$P$6,Data!$D$5:$D$5004,$P$7,Data!$C$5:$C$5004,$P$8,Data!$E$5:$E$5004,$P$9,Data!$F$5:$F$5004,$B97,Data!$G$5:$G$5004,$P$11)+ExOn*SUMIFS(مثال_Example!$V$5:$V$804,مثال_Example!$B$5:$B$804,$P$6,مثال_Example!$D$5:$D$804,$P$7,مثال_Example!$C$5:$C$804,$P$8,مثال_Example!$E$5:$E$804,$P$9,مثال_Example!$F$5:$F$804,$B97,مثال_Example!$G$5:$G$804,$P$11)))/$H97) -> — | M97: =IF($C97=0,"لا توجد بيانات",IF(ROUND(IF(ISNUMBER(D97),D97,0),10)<=KeyA_VW,"Very Weak",IF(ROUND(IF(ISNUMBER(D97),D97,0),10)<KeyA_Weak,"Weak",IF(ROUND(IF(ISNUMBER(E97),E97,0),10)<KeyA_Acc,"Acceptable",IF(ROUND(IF(ISNUMBER(E97),E97,0),10)<=KeyA_Good,"Good",IF(ROUND(IF(ISNUMBER(E97),E97,0),10)<KeyA_Out,"Very Good","Outstanding")))))) -> لا توجد بيانات
